Workbook
Name \0: #N/A
Name \b: #N/A
Name \i: #N/A
Name \P: #REF!
Name \q: #N/A
Name \s: #N/A
Name \z: #N/A
Name _______DAT1: #REF!
Name _______DAT23: #REF!
Name _______DAT25: #REF!
Name ______DAT1: #REF!
Name ______DAT15: #REF!
Name ______DAT16: #REF!
Name ______DAT17: #REF!
Name ______DAT2: #REF!
Name ______DAT22: #REF!
Name ______DAT23: #REF!
Name ______DAT25: #REF!
Name ______DAT8: #REF!
Name ______DAT9: #REF!
Name _____DAT18: #REF!
Name _____DAT19: #REF!
Name _____DAT7: #REF!
Name _____DAT8: #REF!
Name _____DAT9: #REF!
Name ____CAT07: #REF!
Name ____CAT12: #REF!
Name ____CAT21: #REF!
Name ____CAT22: #REF!
Name ____CAT31: #REF!
Name ____CAT33: #REF!
Name ____CAT34: #REF!
Name ____CAT35: #REF!
Name ____CAT36: #REF!
Name ____CAT43: #REF!
Name ____CAT45: #REF!
Name ____CAT46: #REF!
Name ____CAT48: #REF!
Name ____CAT49: #REF!
Name ____CAT52: #REF!
Name ____CAT53: #REF!
Name ____CAT54: #REF!
Name ____CAT55: #REF!
Name ____CAT82: #REF!
Name ____CAT84: #REF!
Name ____DAT1: #REF!
Name ____DAT10: #REF!
Name ____DAT11: #REF!
Name ____DAT12: #REF!
Name ____DAT13: #REF!
Name ____DAT14: #REF!
Name ____DAT15: #REF!
Name ____DAT16: #REF!
Name ____DAT17: #REF!
Name ____DAT2: #REF!
Name ____DAT20: #REF!
Name ____DAT21: #REF!
Name ____DAT22: #REF!
Name ____DAT222: #REF!
Name ____DAT23: #REF!

Sheet Budget
BJ2: =304*Benchmarks!B71 -> 3272.2256
Y3: GBP Version | AF3: USD Version
F6: MMC Fixed FX Rate 25 | X6: Estimated AV Costs based on WH Rates: | Y6: =W45*Y10 -> #REF! | Z6: =Y6 -> #REF! | AE6: Estimated AV Costs based on WH Rates: | AF6: =AD45*AF10 -> #REF! | AG6: =AF6 -> #REF! | AJ6: ='2025 FX Rates'!$F$95 -> 0.00059416
F7: Key Data
G8: 79 | H8: 165 | I8: 34 | J8: 159 | K8: 4550
F9: Heads | H9: 116 | I9: 25 | M9: 78 | N9: 78 | O9: =72+36+36+72+36+24 -> 276 | P9: =O9 -> 276 | Q9: 270 | R9: 270 | S9: 600 | T9: 600 | U9: =S9 -> 600 | V9: 600 | W9: 1050 | X9: 1050 | Y9: 1050 | Z9: =Y9 -> 1050 | AA9: 1050 | AB9: =AA9 -> 1050 | AD9: 1050 | AE9: 1050 | AF9: 1050 | AG9: =AF9 -> 1050 | AH9: 1050 | AI9: =AH9 -> 1050
F10: Area (m²) | G10: 6405 | H10: 8143 | I10: 3280 | J10: 8477 | K10: 350000 | M10: =3114+3916 -> 7030 | N10: =M10 -> 7030 | O10: 25953 | P10: =O10 -> 25953 | Q10: 26000 | R10: 26000 | S10: 67382 | T10: =S10/2 -> 33691 | U10: =S10 -> 67382 | V10: 42000 | W10: 61718 | X10: 61718 | Y10: 66978 | Z10: =Y10 -> 66978 | AA10: =Y10 -> 66978 | AB10: =AA10 -> 66978 | AD10: 61718 | AE10: 61718 | AF10: 66978 | AG10: =AF10 -> 66978 | AH10: =AF10 -> 66978 | AI10: =AH10 -> 66978 | AK10: 4465
F11: Area (ft²) | AK11: =AK10*Benchmarks!B71 -> 48060.813
S13: OW London Project
F14: Ibadan Relocation | G14: Haywards Heath 2019 | H14: Worcester 2020 | I14: Cardiff 2021 | J14: Milton Keynes 2021 | K14: Tower Place 2021 | L14: Low Cost London fit-out (Benchmarks) | M14: Sackville House 5 & 6 (TP Rates) | N14: Sackville house 5 & 6 (Low Cost) | O14: Tower Bridge House (TP Rates) | P14: Tower Bridge House (Low Cost) | Q14: SBB 4th Floor (Half Floor) Short Term | R14: SBB 4th Floor (Half Floor) Long Term | S14: Renew in Baker Street | T14: Renew in Baker Street (1 Floor only) | U14: Renew in Baker Street (Light Touch) | V14: Relocation Option | W14: Norwich Willow House (from Financial Analysis) | X14: Norwich Willow House (MMC Rates) | Y14: Norwich Victoria House Bronze (From Financial Analysis) | Z14: Norwich Victoria House Gold (From Financial Analysis) | AA14: Norwich Victoria House Bronze (MMC Rates) | AB14: Norwich Victoria House Gold (MMC Rates) | AD14: Norwich Willow House (from Financial Analysis) | AE14: Norwich Willow House (MMC Rates) | AF14: Norwich Victoria House Bronze (From Financial Analysis) | AG14: Norwich Victoria House Gold (From Financial Analysis) | AH14: Norwich Victoria House Bronze (MMC Rates) | AI14: Norwich Victoria House Gold (MMC Rates)
AK15: Benchmark - PMO Benchmark | AN15: Option Local Consultant rates | AQ15: Benchmark Previous project rates YEAR | AT15: Option 4 | AW15: Option 5
F16: CAPEX | J16: CAPEX BUDGET | K16: Ongoing Budget | AJ16: Factor | AK16: (NGN) | AL16: (USD) | AO16: (EUR) | AP16: (USD) | AR16: (EUR) | AS16: (USD) | AU16: (EUR) | AV16: (USD) | AX16: (EUR) | AY16: (USD)
F17: Professional Fees | G17: 47582 | H17: ='[1]Final Account'!I9 -> 45360.5 | I17: 20991.5 | J17: 23550 | K17: =4164229 -> 4164229 | M17: =M40*$M$10 -> 39160.545 | N17: =$N$10*N40 -> 39160.545 | O17: =O10*$H$40 -> 144570.93 | P17: =P10*$H$40 -> 144570.93 | Q17: 45000 | R17: =R40*R10 -> 117000 | S17: 750000 | T17: =T40*T10 -> 375000 | U17: =U40*U10 -> 336910 | V17: =V40*$V$10 -> 467483.9 | W17: =#REF! -> #REF! | X17: =X40*$X$10 -> 370308 | Y17: =#REF! -> #REF! | Z17: =#REF! -> #REF! | AA17: =AA40*AA10 -> #REF! | AB17: =AB40*AB10 -> #REF! | AD17: =W17*$W$82 -> #REF! | AE17: =X17*$W$82 -> 499915.8 | AF17: =Y17*$W$82 -> #REF! | AG17: =Z17*$W$82 -> #REF! | AH17: =AA17*$W$82 -> #REF! | AI17: =AB17*$W$82 -> #REF! | AO17: =AO40*$AO$10 -> #REF! | AP17: =AP40*$AO$10 -> 0 | AR17: =AR40*$AR$10 -> 0 | AS17: =AS40*$AO$10 -> 0 | AU17: =SUM(AU18:AU22)*Benchmarks!A91 -> #REF! | AV17: =SUM(AV18:AV22)*Benchmarks!A91 -> #REF! | AX17: =SUM(AX18:AX22)*Benchmarks!A91 -> #REF! | AY17: =SUM(AY18:AY22)*Benchmarks!A91 -> #REF!
F18: Fit-out | G18: 336979 | H18: ='[1]Final Account'!I10 -> 398819.34 | I18: 224045.83 | J18: 541514 | K18: =48062290+2694850+2508770 -> 53265910 | M18: =M41*$M$10 -> 1069883.8 | N18: =$N$10*N41 -> 492100 | O18: =K41*O10 -> 3949743.3 | P18: =L41*P10 -> 1816710 | Q18: =Q41*Q10 -> 260000 | R18: =R41*R10 -> 1560000 | S18: =S41*S10+(S10*S41)*10% -> 11280228 | T18: =T41*T10+(T41+T10)*10% -> 5130760.8 | U18: =U41*U10+(U10*U41)*10% -> 5188414 | V18: =V41*$V$10 -> 6391909.2 | W18: =#REF!+#REF! -> #REF! | X18: =X41*$X$10 -> 3703080 | Y18: =#REF!+#REF!+#REF!+#REF!-Y6 -> #REF! | Z18: =#REF!+#REF!+#REF!+#REF!-Z6 -> #REF! | AA18: =AA41*AA10 -> #REF! | AB18: =AB41*AB10 -> #REF! | AD18: =W18*$W$82 -> #REF! | AE18: =X18*$W$82 -> 4999158 | AF18: =Y18*$W$82 -> #REF! | AG18: =Z18*$W$82 -> #REF! | AH18: =AA18*$W$82 -> #REF! | AI18: =AB18*$W$82 -> #REF! | AK18: =AK41*AK11 -> 1.3938816e+08 | AL18: =AL41*$AK$11 -> 82818.87 | AN18: =AN41 -> 1 | AO18: =AO41*$AO$10 -> 0 | AP18: =AP41*$AO$10 -> 0 | AQ18: =AQ41 -> 1 | AR18: =AR41*$AR$10 -> 0 | AS18: =AS41*$AR$10 -> 0 | AU18: =AU41*$AU$10 -> 0 | AV18: =AV41*$AU$10 -> 0 | AX18: =AX41*$AU$10 -> 0 | AY18: =AY41*$AU$10 -> 0
F19: Security | AK19: =AL19/AJ6 -> 8415241.7 | AL19: 5000
F20: IT | W20: 0 | X20: 0 | Y20: =SUM(#REF!) -> #REF! | Z20: =SUM(#REF!) -> #REF! | AA20: =SUM(#REF!) -> #REF! | AB20: =SUM(#REF!) -> #REF! | AD20: 0 | AE20: 0 | AF20: =Y20*$W$82 -> #REF! | AG20: =Z20*$W$82 -> #REF! | AH20: =AA20*$W$82 -> #REF! | AI20: =AB20*$W$82 -> #REF! | AN20: =#REF! -> #REF! | AO20: =#REF!*$AO$10 -> #REF! | AP20: =#REF!*$AO$10 -> #REF! | AQ20: =#REF! -> #REF! | AR20: =#REF!*$AR$10 -> #REF! | AS20: =#REF!*$AR$10 -> #REF! | AU20: =#REF!*$AU$10 -> #REF! | AV20: =#REF!*$AU$10 -> #REF! | AX20: =#REF!*$AU$10 -> #REF! | AY20: =#REF!*$AU$10 -> #REF!
F21: Furniture | G21: 144402 | H21: ='[1]Final Account'!I11 -> 193768.67 | I21: 0 | J21: 150288 | K21: =7975676 -> 7975676 | M21: =M44*$M$10 -> 160197.15 | N21: =$N$10*N44 -> 160197.15 | O21: =K44*O10 -> 591407.77 | P21: =L44*P10 -> 591407.77 | Q21: 0 | R21: 0 | S21: =S44*S10 -> 1535477.1 | T21: =T10*T44 -> 767738.57 | U21: =U44*U10 -> 1347640 | V21: =V44*$V$10 -> 957081.12 | W21: =#REF! -> #REF! | X21: =X44*$X$10 -> 1419514 | Y21: =#REF! -> #REF! | Z21: =#REF! -> #REF! | AA21: =AA44*AA10 -> 1540494 | AB21: =AB44*AB10 -> 1540494 | AD21: =W21*$W$82 -> #REF! | AE21: =X21*$W$82 -> 1916343.9 | AF21: =Y21*$W$82 -> #REF! | AG21: =Z21*$W$82 -> #REF! | AH21: =AA21*$W$82 -> 2079666.9 | AI21: =AB21*$W$82 -> 2079666.9 | AK21: =AK44*AK11 -> 70200000 | AL21: =AL44*AK11 -> 41710.032 | AN21: =AN44 -> 1 | AO21: =AO44*$AO$10 -> #REF! | AP21: =AP44*$AO$10 -> 0 | AQ21: =AQ44 -> 1 | AR21: =AR44*$AR$10 -> 0 | AS21: =AS44*$AR$10 -> 0 | AU21: =AU44*$AU$10 -> #REF! | AV21: =AV44*$AU$10 -> 0 | AX21: =AX44*$AU$10 -> 0 | AY21: =AY44*$AU$10 -> 0
F22: AV & Equipment | G22: 108580.29 | H22: ='[1]Final Account'!I12 -> 70503 | I22: 30111 | J22: 130681 | K22: =4578826 -> 4578826 | M22: =M45*$M$10 -> 105450 | N22: =N45*$N$10 -> 91968.991 | O22: =L45*O10 -> 389295 | P22: =P10*K45 -> 339526.49 | Q22: 50000 | R22: =R45*R10 -> 340600 | S22: =S45*S10 -> 1010730 | T22: =T45*T10 -> 505365 | U22: =U45*U10 -> 881515.58 | V22: =V45*$V$10 -> 630000 | W22: =#REF! -> #REF! | X22: =X45*X10 -> 925770 | Y22: =Y6 -> #REF! | Z22: =Z6 -> #REF! | AA22: =AA45*AA10 -> 1004670 | AB22: =AB45*AB10 -> 1004670 | AD22: =W22*$W$82 -> #REF! | AE22: =X22*$W$82 -> 1249789.5 | AF22: =Y22*$W$82 -> #REF! | AG22: =Z22*$W$82 -> #REF! | AH22: =AA22*$W$82 -> 1356304.5 | AI22: =AB22*$W$82 -> 1356304.5 | AN22: =AN45 -> 1 | AO22: =AO45*$AO$10 -> #REF! | AP22: =AP45*$AO$10 -> 0 | AQ22: =AQ45 -> 1 | AR22: =AR45*$AR$10 -> 0 | AS22: =AS45*$AR$10 -> 0 | AU22: =AU45*$AU$10 -> #REF! | AV22: =AV45*$AU$10 -> 0 | AX22: =AX45*$AU$10 -> 0 | AY22: =AY45*$AU$10 -> 0
F23: Total | G23: =SUM(G17:G22) -> 637543.29 | H23: =SUM(H17:H22) -> 708451.51 | I23: =SUM(I17:I22) -> 275148.33 | J23: =SUM(J17:J22) -> 846033 | K23: =SUM(K17:K22) -> 69984641 | M23: =SUM(M17:M22) -> 1374691.5 | N23: =SUM(N17:N22) -> 783426.68 | O23: =SUM(O17:O22) -> 5075017 | P23: =SUM(P17:P22) -> 2892215.2 | Q23: =SUM(Q17:Q22) -> 355000 | R23: =SUM(R17:R22) -> 2017600 | S23: =SUM(S17:S22) -> 14576435 | T23: =SUM(T17:T22) -> 6778864.4 | ... X23: =SUM(X17:X22) -> 6418672 | Y23: =Y22+Y21+Y20+Y18+Y17 -> #REF! | Z23: =Z22+Z21+Z20+Z18+Z17 -> #REF! | AA23: =AA22+AA21+AA20+AA18+AA17 -> #REF! | AB23: =AB22+AB21+AB20+AB18+AB17 -> #REF! | AD23: =SUM(AD17:AD22) -> #REF! | AE23: =SUM(AE17:AE22) -> 8665207.2 | AF23: =AF22+AF21+AF20+AF18+AF17 -> #REF! | AG23: =AG22+AG21+AG20+AG18+AG17 -> #REF! | AH23: =AH22+AH21+AH20+AH18+AH17 -> #REF! | AI23: =AI22+AI21+AI20+AI18+AI17 -> #REF! | AK23: =SUM(AK17:AK22) -> 2.180034e+08 | AL23: =SUM(AL17:AL22) -> 129528.9 | AO23: =SUM(AO17:AO22) -> #REF! | AP23: =SUM(AP17:AP22) -> #REF! | AR23: =SUM(AR17:AR22) -> #REF! | AS23: =SUM(AS17:AS22) -> #REF! | AU23: =SUM(AU17:AU22) -> #REF! | AV23: =SUM(AV17:AV22) -> #REF! | AX23: =SUM(AX17:AX22) -> #REF! | AY23: =SUM(AY17:AY22) -> #REF!
F24: Rate per SQM | AK24: =AK23/AK10 -> 48824.95 | AL24: =AL23/AK10 -> 29.009833 | AO24: =AO23/AO10 -> #REF! | AR24: =AR23/AR10 -> #REF!
F25: Rate per SQFT | AK25: =AK23/AK11 -> 4535.9907 | AL25: =AL23/AK11 -> 2.6951042
F27: LL Contribution | AK27: =AK51*AK11 -> 0 | AL27: =AL51*AK11 -> 0
F29: P&L - One Off
F30: Moves | G30: 31699 | H30: ='[1]Final Account'!I15 -> 20343.65 | I30: 49200 | K30: 1000000 | M30: =N30 -> #VALUE! | N30: =N9*Benchmarks!C90 -> #VALUE! | O30: =Benchmarks!C90*Budget!O9 -> #VALUE! | P30: =O30 -> #VALUE! | Q30: =Benchmarks!C90*270 -> #VALUE! | R30: =Q30 -> #VALUE! | S30: =S49*S9*2 -> #VALUE! | T30: =T49*T9*2 -> #VALUE! | U30: =U9*U49*2 -> #VALUE! | V30: =V9*V49 -> #VALUE! | W30: =#REF! -> #REF! | X30: =X49*750 -> 83250 | Y30: =#REF! -> #REF! | Z30: =#REF! -> #REF! | AA30: =AA49*750 -> #REF! | AB30: =AB49*750 -> #REF! | AD30: =W30*$W$82 -> #REF! | AE30: =X30*$W$82 -> 112387.5 | AF30: =Y30*$W$82 -> #REF! | AG30: =Z30*$W$82 -> #REF! | AH30: =AA30*$W$82 -> #REF! | AI30: =AB30*$W$82 -> #REF! | AK30: =AK49*AK11 -> 7745192.3 | AL30: =AL49*AK11 -> 4601.8835 | AO30: =AO49*AO9 -> 0 | AP30: =AP49*AO9 -> 0 | AR30: =AR49*AR9 -> 0 | AS30: =AS49*AR9 -> 0 | AU30: =AU49*AU9 -> 0 | AV30: =AV49*AU9 -> 0 | AX30: =AX49*AX9 -> 0 | AY30: =AY49*AX9 -> 0
F31: MMC Tech Costs (5y)
F32: MMC Tech Costs (5y) | S32: =S50*S10 -> 1010730 | T32: =T50*T10 -> 505365 | U32: =U50*U10 -> 1010730 | V32: =V50*V10 -> 630000 | W32: =#REF! -> #REF! | X32: =X50*X10 -> 925770 | Y32: =#REF! -> #REF! | Z32: =#REF! -> #REF! | AA32: =AA50*AA10 -> #REF! | AB32: =AB50*AB10 -> #REF! | AD32: =W32*$W$82 -> #REF! | AE32: =X32*$W$82 -> 1249789.5 | AF32: =Y32*$W$82 -> #REF! | AG32: =Z32*$W$82 -> #REF! | AH32: =AA32*$W$82 -> #REF! | AI32: =AB32*$W$82 -> #REF! | AK32: =AK50*AK10 -> 0 | AL32: =AL50*AK10 -> 0 | AO32: =AO50*AO10 -> 0 | AP32: =AP50*AO10 -> 0 | AR32: =AR50*AR10 -> 0 | AS32: =AS50*AR10 -> 0 | AU32: =AU10*AU50 -> 0 | AV32: =AV50*AU10 -> 0 | AX32: =AX10*AX50 -> 0 | AY32: =AY50*AX10 -> 0
F35: GRAND TOTAL | G35: Full-fit out | H35: Full Refurb | I35: light-mid touch refurb | J35: Full Fit-out | W35: =W32+W30+W23 -> #REF! | X35: =X32+X30+X23 -> 7427692 | Y35: =Y32+Y30+Y23 -> #REF! | Z35: =Z32+Z30+Z23 -> #REF! | AA35: =AA32+AA30+AA23 -> #REF! | AB35: =AB32+AB30+AB23 -> #REF! | AD35: =AD32+AD30+AD23 -> #REF! | AE35: =AE32+AE30+AE23 -> 10027384 | AF35: =AF32+AF30+AF23 -> #REF! | AG35: =AG32+AG30+AG23 -> #REF! | AH35: =AH32+AH30+AH23 -> #REF! | AI35: =AI32+AI30+AI23 -> #REF! | AK35: =AK32+AK30+AK23-AK27 -> 2.257486e+08 | AL35: =AL32+AL30+AL23-AL27 -> 134130.79 | AO35: =AO32+AO30+AO23 -> #REF! | AP35: =AP32+AP30+AP23 -> #REF! | AR35: =AR32+AR30+AR23 -> #REF! | AS35: =AS32+AS30+AS23 -> #REF! | AU35: =AU32+AU30+AU23 -> #REF! | AV35: =AV32+AV30+AV23 -> #REF! | AX35: =AX32+AX30+AX23 -> #REF! | AY35: =AY32+AY30+AY23 -> #REF!
G36: 5% sit-stand (all rest are with crank) | H36: Full Sit-stand | I36: Reused Furniture | J36: Full-Sit Stand + HS Monitor Arms
G37: Old AV Standards | H37: All DTENs | I37: New AV Standards | J37: New AV Standards
J38: Improved LED Lighting (GCL) circa 4£/ft²
F39: Rates (/ft²) | AD39: Rates ($/ft²) | AJ39: Factor | AN39: Factor | AQ39: Factor | AT39: Factor | AW39: Factor
F40: Professional Fees | G40: =G17/$G$10 -> 7.4288837 | H40: =H17/$H$10 -> 5.57049 | I40: =I17/$I$10 -> 6.3998476 | J40: =J17/$J$10 -> 2.7781055 | K40: =K17/$K$10 -> 11.897797 | M40: =O40 -> 5.57049 | N40: =O40 -> 5.57049 | O40: =O17/$O$10 -> 5.57049 | P40: =P17/$P$10 -> 5.57049 | Q40: =Q17/Q10 -> 1.7307692 | R40: 4.5 | S40: =S17/S10 -> 11.130569 | T40: =S40 -> 11.130569 | U40: 5 | V40: =S40 -> 11.130569 | W40: =W17/$W$10 -> #REF! | X40: 6 | Y40: =Y17/Y10 -> #REF! | Z40: =Z17/Z10 -> #REF! | AA40: =Z40 -> #REF! | AB40: =AA40 -> #REF! | AD40: =W40*$W$82 -> #REF! | AE40: =X40*$W$82 -> 8.1 | AF40: =Y40*$W$82 -> #REF! | AG40: =Z40*$W$82 -> #REF! | AH40: =AA40*$W$82 -> #REF! | AI40: =AB40*$W$82 -> #REF! | AJ40: 1 | AK40: =Benchmarks!$C$91*AJ40 -> 436.0895 | AL40: =AK40*$AJ$6 -> 0.25910694 | AO40: =Benchmarks!E91 -> #REF! | AP40: =Benchmarks!I91 -> 0 | AR40: =10%*SUM(AR41:AR45) -> 158.32569 | AS40: =AR40*$AJ$6 -> 0.094070792 | AU40: =(AU41+AU44+AU45)*Benchmarks!$A$91 -> #REF! | AV40: =Benchmarks!$G$91 -> 0 | AX40: =(AX41+AX44+AX45)*Benchmarks!$A$91 -> 395.57502 | AY40: =Benchmarks!$G$91 -> 0
F41: Fit Out | G41: =G18/$G$10 -> 52.611866 | H41: =H18/$H$10 -> 48.976954 | I41: =I18/$I$10 -> 68.306655 | J41: =J18/$J$10 -> 63.880382 | K41: =K18/$K$10 -> 152.18831 | L41: 70 | M41: =O41 -> 152.18831 | N41: =P41 -> 70 | O41: =O18/$O$10 -> 152.18831 | P41: =P18/$P$10 -> 70 | Q41: 10 | R41: 60 | S41: =O41 -> 152.18831 | T41: =S41 -> 152.18831 | U41: =P41 -> 70 | V41: =S41 -> 152.18831 | W41: =W18/$W$10 -> #REF! | X41: 60 | Y41: =Y18/Y10 -> #REF! | Z41: =Z18/Z10 -> #REF! | AA41: =Y41 -> #REF! | AB41: =Z41 -> #REF! | AD41: =W41*$W$82 -> #REF! | AE41: =X41*$W$82 -> 81 | AF41: =Y41*$W$82 -> #REF! | AG41: =Z41*$W$82 -> #REF! | AH41: =AA41*$W$82 -> #REF! | AI41: =AB41*$W$82 -> #REF! | AJ41: 1 | AK41: =Benchmarks!$C$76*AJ41 -> 2900.2456 | AL41: =AK41*$AJ$6 -> 1.7232099 | AN41: 1 | AO41: =Benchmarks!E92*AN41 -> 2900.2456 | AP41: =Benchmarks!I92 -> 0 | AQ41: 1 | AR41: =527.7523*AQ41 -> 527.7523 | AS41: =AR41*$AJ$6 -> 0.31356931 | AT41: 1 | AU41: =AK41 -> 2900.2456 | AV41: =AL41 -> 1.7232099 | AW41: 1 | AX41: =AO41 -> 2900.2456 | AY41: =AP41*80% -> 0
F42: Security | AJ42: 0.1 | AK42: =Benchmarks!$L$71*AJ42 -> 656.71392 | AL42: =AK42*$AJ$6 -> 0.39019315
F43: IT | AJ43: 0.1 | AK43: =Benchmarks!$T$71*AJ43 -> 1067.1601 | AL43: =AK43*$AJ$6 -> 0.63406386
F44: Furniture | G44: =G21/$G$10 -> 22.545199 | H44: =H21/$H$10 -> 23.795735 | I44: =I21/$I$10 -> 0 | J44: =J21/$J$10 -> 17.728914 | K44: =K21/$K$10 -> 22.787646 | L44: =K44 -> 22.787646 | M44: =O44 -> 22.787646 | N44: =P44 -> 22.787646 | O44: =O21/$O$10 -> 22.787646 | P44: =P21/$P$10 -> 22.787646 | Q44: 0 | R44: 0 | S44: =O44 -> 22.787646 | T44: =S44 -> 22.787646 | U44: 20 | V44: =P44 -> 22.787646 | W44: =W21/$W$10 -> #REF! | X44: 23 | Y44: =Y21/$Y$10 -> #REF! | Z44: =Z21/$Z$10 -> #REF! | AA44: =X44 -> 23 | AB44: =X44 -> 23 | AD44: =W44*$W$82 -> #REF! | AE44: =X44*$W$82 -> 31.05 | AF44: =Y44*$W$82 -> #REF! | AG44: =Z44*$W$82 -> #REF! | AH44: =AA44*$W$82 -> 31.05 | AI44: =AB44*$W$82 -> 31.05 | AJ44: 1 | AK44: ='Local consultant_Summary'!E27/AK11 -> 1460.6494 | AL44: =AK44*$AJ$6 -> 0.86785947 | AN44: 1 | AO44: =Benchmarks!E95*AN44 -> #REF! | AP44: =Benchmarks!I95 -> 0 | AQ44: 1 | AR44: =527.7523*AQ44 -> 527.7523 | AS44: =AR44*$AJ$6 -> 0.31356931 | AT44: 1 | AU44: =AO44 -> #REF! | AV44: =AP44 -> 0 | AW44: 1 | AX44: =AR44 -> 527.7523 | AY44: =AS44 -> 0.31356931
F45: AV & Equipment | G45: =G22/$G$10 -> 16.952426 | H45: =H22/$H$10 -> 8.6581113 | I45: =I22/$I$10 -> 9.1801829 | J45: =J22/$J$10 -> 15.415949 | K45: =K22/$K$10 -> 13.08236 | L45: 15 | M45: =O45 -> 15 | N45: =P45 -> 13.08236 | O45: =O22/$O$10 -> 15 | P45: =P22/$P$10 -> 13.08236 | Q45: =Q22/Q10 -> 1.9230769 | R45: 13.1 | S45: =O45 -> 15 | T45: =S45 -> 15 | U45: =P45 -> 13.08236 | V45: =S45 -> 15 | W45: =W22/$W$10 -> #REF! | X45: 15 | Y45: =Y22/$Y$10 -> #REF! | Z45: =Z22/$Z$10 -> #REF! | AA45: 15 | AB45: 15 | AD45: =W45*$W$82 -> #REF! | AE45: =X45*$W$82 -> 20.25 | AF45: =Y45*$W$82 -> #REF! | AG45: =Z45*$W$82 -> #REF! | AH45: =AA45*$W$82 -> 20.25 | AI45: =AB45*$W$82 -> 20.25 | AK45: =Benchmarks!$C$96*AJ45 -> 0 | AL45: =Benchmarks!$G$96*AJ45 -> 0 | AN45: 1 | AO45: =Benchmarks!E96*AN45 -> #REF! | AP45: =Benchmarks!I96 -> 0 | AQ45: 1 | AR45: =527.7523*AQ45 -> 527.7523 | AS45: =AR45*AJ6 -> 0.31356931 | AT45: 1 | AU45: =AO45 -> #REF! | AV45: =AP45 -> 0 | AW45: 1 | AX45: =AR45 -> 527.7523 | AY45: =AS45 -> 0.31356931
F46: Total | AK46: =SUM(AK40:AK45) -> 6520.8586 | AL46: =SUM(AL40:AL45) -> 3.8744333 | AO46: =SUM(AO40:AO45) -> #REF! | AP46: =SUM(AP40:AP45) -> 0 | AR46: =SUM(AR40:AR45) -> 1741.5826 | AS46: =SUM(AS40:AS45) -> 1.0347787 | AU46: =SUM(AU40:AU45) -> #REF! | AV46: =SUM(AV40:AV45) -> 1.7232099 | AX46: =SUM(AX40:AX45) -> 4351.3252 | AY46: =SUM(AY40:AY45) -> 0.62713861
F49: Moves (/person) | G49: =Benchmarks!C90 -> Global Benchmark | H49: =G49 -> Global Benchmark | I49: =H49 -> Global Benchmark | J49: =I49 -> Global Benchmark | K49: =J49 -> Global Benchmark | L49: =K49 -> Global Benchmark | M49: =L49 -> Global Benchmark | N49: =M49 -> Global Benchmark | O49: =N49 -> Global Benchmark | ... T49: =S49 -> Global Benchmark | U49: =S49 -> Global Benchmark | V49: =S49 -> Global Benchmark | W49: =W30/750 -> #REF! | X49: 111 | Y49: =Y30/750 -> #REF! | Z49: =Z30/750 -> #REF! | AA49: =Y49 -> #REF! | AB49: =Z49 -> #REF! | AD49: =W49*$W$82 -> #REF! | AE49: =X49*$W$82 -> 149.85 | AF49: =Y49*$W$82 -> #REF! | AG49: =Z49*$W$82 -> #REF! | AH49: =AA49*$W$82 -> #REF! | AI49: =AB49*$W$82 -> #REF! | AJ49: 1 | AK49: ='Local consultant_Summary'!E35/Budget!AK11 -> 161.154 | AL49: =AK49*AJ6 -> 0.095751261 | AO49: =AP49/Benchmarks!B67 -> 161.154 | AP49: =AL49 -> 0.095751261 | AR49: =AO49 -> 161.154 | AS49: =AP49 -> 0.095751261 | AU49: =AR49 -> 161.154 | AV49: =AS49 -> 0.095751261 | AX49: =AU49 -> 161.154 | AY49: =AV49 -> 0.095751261
F50: MMC Tech Costs (5y) | G50: 15 | H50: =G50 -> 15 | I50: =H50 -> 15 | J50: =I50 -> 15 | K50: =J50 -> 15 | L50: =K50 -> 15 | M50: =L50 -> 15 | N50: =M50 -> 15 | O50: =N50 -> 15 | ... T50: =S50 -> 15 | U50: =S50 -> 15 | V50: =S50 -> 15 | W50: =W32/W10 -> #REF! | X50: 15 | Y50: =Y32/Y10 -> #REF! | Z50: =Z32/Z10 -> #REF! | AA50: =Y50 -> #REF! | AB50: =Z50 -> #REF! | AD50: =W50*$W$82 -> #REF! | AE50: =X50*$W$82 -> 20.25 | AF50: =Y50*$W$82 -> #REF! | AG50: =Z50*$W$82 -> #REF! | AH50: =AA50*$W$82 -> #REF! | AI50: =AB50*$W$82 -> #REF! | AL50: =Benchmarks!B83*Budget!AJ50 -> 0 | AO50: =AP50/Benchmarks!B67 -> 0 | AP50: =AL50 -> 0 | AR50: =AO50 -> 0 | AS50: =AL50 -> 0 | AU50: =AR50 -> 0 | AV50: =AS50 -> 0 | AX50: =AU50 -> 0 | AY50: =AV50 -> 0
...

Sheet Benchmarks
A1: Country | B1: City | C1: CAT B AGILE | F1: Furniture Trad | I1: Furniture Agile | L1: Security | M1: AV traditional | P1: AV AGILE | S1: Fees | T1: IT | W1: Contingency | X1: Traditional Fitout | Z1: Agile Fit-out | AC1: Furniture
C2: LOW | D2: MED | E2: HIGH | F2: LOW | G2: MED | H2: HIGH | I2: LOW | J2: MED | K2: HIGH | L2: LOW, MED & High | M2: LOW | N2: MED | O2: HIGH | P2: LOW | Q2: MED | R2: HIGH | S2: % | T2: LOW | U2: MED | V2: HIGH | W2: % | X2: LOW | Y2: HIGH | Z2: LOW | AA2: HIGH | AC2: INSTALL | AD2: LOGISTICS | AE2: IMPORT Tax | AF2: TIME (wks)
A3: Angola | B3: Luanda | C3: 995 | D3: 1194 | E3: 1830 | F3: 95+ | G3: 120+ | H3: 165+ | I3: 145+ | J3: 175+ | K3: 220+ | L3: 40+ | M3: 60+ | N3: 100+ | O3: 180+ | P3: 85+ | Q3: 130+ | R3: 245+ | S3: 0.22 | T3: 65+ | V3: 125+ | W3: 0.1 | X3: 1,740+ | Y3: 3,239+ | Z3: 1,769+ | AA3: 3,271+
A4: Austria | B4: Vienna | C4: 547 | D4: 670 | E4: 1022 | F4: 105 | G4: 132 | H4: 182 | I4: 160 | J4: 193 | K4: 242 | L4: 40 | M4: 60 | N4: 100 | O4: 180 | P4: 85 | Q4: 131 | R4: 246 | S4: 0.18 | T4: 65 | V4: 125 | W4: 0.1 | X4: 1084 | Y4: 2056 | Z4: 1150 | AA4: 2150
A5: Belgium | B5: Brussels | C5: 436 | D5: 551 | E5: 847 | F5: 105 | G5: 132 | H5: 182 | I5: 160 | J5: 193 | K5: 242 | L5: 40 | M5: 60 | N5: 100 | O5: 180 | P5: 85 | Q5: 131 | R5: 246 | S5: 0.18 | T5: 65 | V5: 125 | W5: 0.1 | X5: 933 | Y5: 1816 | Z5: 1006 | AA5: 1923
A6: Botswana | B6: Gaborone | C6: 752 | D6: 896 | E6: 1368 | F6: 151 | G6: 191 | H6: 262 | I6: 231 | J6: 278 | K6: 350 | L6: 48 | M6: 72 | N6: 120 | O6: 216 | P6: 102 | Q6: 157 | R6: 296 | S6: 0.19 | T6: 78 | V6: 150 | W6: 0.1 | X6: 1477 | Y6: 2738 | Z6: 1568 | AA6: 2863
A7: Bulgaria | B7: Sofia | C7: 320 | D7: 498 | E7: 682 | F7: 108 | G7: 137 | H7: 188 | I7: 165 | J7: 200 | K7: 251 | L7: 40 | M7: 60 | N7: 100 | O7: 180 | P7: 85 | Q7: 131 | R7: 246 | S7: 0.17 | T7: 65 | V7: 125 | W7: 0.1 | X7: 773 | Y7: 1586 | Z7: 857 | AA7: 1706
A8: Croatia | B8: Zagreb | C8: 445 | D8: 540 | E8: 782 | F8: 109 | G8: 138 | H8: 190 | I8: 167 | J8: 201 | K8: 253 | L8: 40 | M8: 60 | N8: 100 | O8: 180 | P8: 85 | Q8: 131 | R8: 246 | S8: 0.21 | T8: 65 | V8: 125 | W8: 0.1 | X8: 973 | Y8: 1778 | Z8: 1052 | AA8: 1896
A9: Denmark | B9: Copenhagen | C9: 588 | D9: 728 | E9: 1192 | F9: 110 | G9: 139 | H9: 191 | I9: 168 | J9: 203 | K9: 255 | L9: 40 | M9: 60 | N9: 100 | O9: 180 | P9: 85 | Q9: 131 | R9: 246 | S9: 0.26 | T9: 65 | V9: 125 | W9: 0.1 | X9: 1220 | Y9: 2447 | Z9: 1292 | AA9: 2541
A10: Egypt | B10: Cairo | C10: 525 | D10: 783 | E10: 1142 | F10: 182 | G10: 230 | H10: 317 | I10: 278 | J10: 336 | K10: 422 | L10: 64 | M10: 96 | N10: 160 | O10: 288 | P10: 136 | Q10: 209 | R10: 394 | S10: 0.15 | T10: 104 | V10: 200 | W10: 0.1 | X10: 1247 | Y10: 2586 | Z10: 1383 | AA10: 2778
A11: Estonia | B11: Tallinn | C11: 431 | D11: 522 | E11: 857 | F11: 109 | G11: 138 | H11: 190 | I11: 167 | J11: 201 | K11: 253 | L11: 40 | M11: 60 | N11: 100 | O11: 180 | P11: 85 | Q11: 131 | R11: 246 | S11: 0.14 | T11: 65 | V11: 125 | W11: 0.1 | X11: 903 | Y11: 1782 | Z11: 978 | AA11: 1888
A12: Ethiopia | B12: Addis Ababa | C12: 768 | D12: 917 | E12: 1409 | F12: 161 | G12: 203 | H12: 279 | I12: 245 | J12: 296 | K12: 372 | L12: 52 | M12: 78 | N12: 130 | O12: 234 | P12: 110 | Q12: 170 | R12: 320 | S12: 0.17 | T12: 85 | V12: 163 | W12: 0.1 | X12: 1508 | Y12: 2815 | Z12: 1606 | AA12: 2950
A13: Finland | B13: Helsinki | C13: 775 | D13: 928 | E13: 1382 | F13: 114 | G13: 144 | H13: 198 | I13: 174 | J13: 210 | K13: 264 | L13: 40 | M13: 60 | N13: 100 | O13: 180 | P13: 85 | Q13: 131 | R13: 246 | S13: 0.16 | T13: 65 | V13: 125 | W13: 0.1 | X13: 1386 | Y13: 2530 | Z13: 1442 | AA13: 2606
A14: France | B14: Paris | C14: 737 | D14: 890 | E14: 1384 | F14: 105 | G14: 132 | H14: 182 | I14: 160 | J14: 193 | K14: 242 | L14: 40 | M14: 60 | N14: 100 | O14: 180 | P14: 85 | Q14: 131 | R14: 246 | S14: 0.18 | T14: 65 | V14: 125 | W14: 0.1 | X14: 1344 | Y14: 2550 | Z14: 1397 | AA14: 2620
A15: Germany | B15: Berlin | C15: 686 | D15: 884 | E15: 1369 | F15: 103 | G15: 130 | H15: 178 | I15: 157 | J15: 189 | K15: 238 | L15: 40 | M15: 60 | N15: 100 | O15: 180 | P15: 85 | Q15: 131 | R15: 246 | S15: 0.26 | T15: 65 | V15: 125 | W15: 0.1 | X15: 1354 | Y15: 2687 | Z15: 1413 | AA15: 2761
... A36: Netherlands | B36: Amsterdam | C36: 650 | D36: 800 | E36: 1090 | F36: 105 | G36: 132 | H36: 182 | I36: 160 | J36: 193 | K36: 242 | L36: 40 | M36: 60 | N36: 100 | O36: 180 | P36: 85 | Q36: 131 | R36: 246 | S36: 0.18 | T36: 65 | V36: 125 | W36: 0.1 | X36: 1224 | Y36: 2147 | Z36: 1284 | AA36: 2238
A37: Nigeria | B37: Abuja | C37: 1089 | D37: 1445 | E37: 2048 | F37: 95+ | G37: 120+ | H37: 165+ | I37: 145+ | J37: 175+ | K37: 220+ | L37: 40+ | M37: 60+ | N37: 100+ | O37: 180+ | P37: 85+ | Q37: 130+ | R37: 245+ | S37: 0.22 | T37: 65+ | V37: 125+ | W37: 0.1 | X37: 1,871+ | Y37: 3,547+ | Z37: 1,895+ | AA37: 3,564+
A38: Norway | B38: Oslo | C38: 697 | D38: 1100 | E38: 1667 | F38: 114 | G38: 144 | H38: 198 | I38: 174 | J38: 210 | K38: 264 | L38: 40 | M38: 60 | N38: 100 | O38: 180 | P38: 85 | Q38: 131 | R38: 246 | S38: 0.19 | T38: 65 | V38: 125 | W38: 0.1 | X38: 1312 | Y38: 2981 | Z38: 1374 | AA38: 3040
A39: Oman | B39: Muscat | C39: 672 | D39: 877 | E39: 1271 | F39: 126 | G39: 160 | H39: 219 | I39: 193 | J39: 233 | K39: 293 | L39: 42 | M39: 63 | N39: 105 | O39: 189 | P39: 89 | Q39: 137 | R39: 259 | S39: 0.18 | T39: 68 | V39: 131 | W39: 0.1 | X39: 1293 | Y39: 2466 | Z39: 1368 | AA39: 2565
A40: Poland | B40: Warsaw | C40: 486 | D40: 604 | E40: 863 | F40: 109 | G40: 138 | H40: 190 | I40: 167 | J40: 201 | K40: 253 | L40: 40 | M40: 60 | N40: 100 | O40: 180 | P40: 85 | Q40: 131 | R40: 246 | S40: 0.17 | T40: 65 | V40: 125 | W40: 0.1 | X40: 1000 | Y40: 1834 | Z40: 1073 | AA40: 1942
A41: Portugal | B41: Lisbon | C41: 454 | D41: 608 | E41: 922 | F41: 105 | G41: 132 | H41: 182 | I41: 160 | J41: 193 | K41: 242 | L41: 40 | M41: 60 | N41: 100 | O41: 180 | P41: 85 | Q41: 131 | R41: 246 | S41: 0.15 | T41: 65 | V41: 125 | W41: 0.1 | X41: 935 | Y41: 1873 | Z41: 1005 | AA41: 1973
A42: Qatar | B42: Doha | C42: 782 | D42: 1072 | E42: 1516 | F42: 125 | G42: 158 | H42: 218 | I42: 191 | J42: 231 | K42: 290 | L42: 42 | M42: 63 | N42: 105 | O42: 189 | P42: 89 | Q42: 137 | R42: 259 | S42: 0.18 | T42: 68 | V42: 131 | W42: 0.1 | X42: 1443 | Y42: 2798 | Z42: 1509 | AA42: 2879
A43: Romania | B43: Bucharest | C43: 346 | D43: 468 | E43: 751 | F43: 111 | G43: 140 | H43: 193 | I43: 170 | J43: 205 | K43: 257 | L43: 40 | M43: 60 | N43: 100 | O43: 180 | P43: 85 | Q43: 131 | R43: 246 | S43: 0.18 | T43: 65 | V43: 125 | W43: 0.1 | X43: 819 | Y43: 1699 | Z43: 903 | AA43: 1818
A44: Russia | B44: Moscow | C44: 480 | D44: 625 | E44: 1000 | F44: 138 | G44: 174 | H44: 239 | I44: 210 | J44: 254 | K44: 319 | L44: 50 | M44: 75 | N44: 125 | O44: 225 | P44: 106 | Q44: 164 | R44: 308 | S44: 0.12 | T44: 81 | V44: 156 | W44: 0.1 | X44: 1035 | Y44: 2102 | Z44: 1131 | AA44: 2238
A45: Saudi Arabia | B45: Riyadh | C45: 725 | D45: 930 | E45: 1336 | F45: 141 | G45: 178 | H45: 244 | I45: 215 | J45: 259 | K45: 326 | L45: 48 | M45: 72 | N45: 120 | O45: 216 | P45: 102 | Q45: 157 | R45: 296 | S45: 0.17 | T45: 78 | V45: 150 | W45: 0.1 | X45: 1403 | Y45: 2630 | Z45: 1487 | AA45: 2746
A46: Serbia | B46: Belgrade | C46: 340 | D46: 418 | E46: 648 | F46: 135 | G46: 170 | H46: 234 | I46: 206 | J46: 249 | K46: 312 | L46: 48 | M46: 72 | N46: 120 | O46: 216 | P46: 102 | Q46: 157 | R46: 296 | S46: 0.17 | T46: 78 | V46: 150 | W46: 0.1 | X46: 875 | Y46: 1684 | Z46: 981 | AA46: 1843
A47: Slovakia | B47: Bratislava | C47: 319 | D47: 528 | E47: 690 | F47: 109 | G47: 138 | H47: 190 | I47: 167 | J47: 201 | K47: 253 | L47: 40 | M47: 60 | N47: 100 | O47: 180 | P47: 85 | Q47: 131 | R47: 246 | S47: 0.15 | T47: 65 | V47: 125 | W47: 0.1 | X47: 760 | Y47: 1574 | Z47: 843 | AA47: 1692
A48: South Africa | B48: Cape Town | C48: 556 | D48: 711 | E48: 1085 | F48: 142 | G48: 179 | H48: 246 | I48: 216 | J48: 261 | K48: 328 | L48: 48 | M48: 72 | N48: 120 | O48: 216 | P48: 102 | Q48: 157 | R48: 296 | S48: 0.18 | T48: 78 | V48: 150 | W48: 0.1 | X48: 1186 | Y48: 2309 | Z48: 1283 | AA48: 2445
A49: South Africa | B49: Johannesburg | C49: 551 | D49: 704 | E49: 1075 | F49: 142 | G49: 179 | H49: 246 | I49: 216 | J49: 261 | K49: 328 | L49: 48 | M49: 72 | N49: 120 | O49: 216 | P49: 102 | Q49: 157 | R49: 296 | S49: 0.18 | T49: 78 | V49: 150 | W49: 0.1 | X49: 1178 | Y49: 2295 | Z49: 1276 | AA49: 2432
... A65: Zambia | B65: Lusaka | C65: 765 | D65: 907 | E65: 1342 | F65: 156 | G65: 197 | H65: 271 | I65: 238 | J65: 287 | K65: 361 | L65: 50 | M65: 75 | N65: 125 | O65: 225 | P65: 106 | Q65: 164 | R65: 308 | S65: 0.19 | T65: 81 | V65: 156 | W65: 0.1 | X65: 1510 | Y65: 2735 | Z65: 1605 | AA65: 2869
A66: Nigeria | B66: Abuja | L66: 42 | M66: 63 | N66: 105 | O66: 189 | S66: 0.1785 | T66: 68.25 | U66: 0 | V66: 131.25 | W66: 0.105 | X66: 914.55 | Y66: 1769.25 | Z66: 994.35 | AA66: 1886.85
A67: USD/NGN | B67: ='2025 FX Rates'!$F$95 -> 0.00059416 | C67: =C66/$B$67 -> 0 | D67: =D66/$B$67 -> 0 | E67: =E66/$B$67 -> 0 | F67: =F66/$B$67 -> 0 | G67: =G66/$B$67 -> 0 | H67: =H66/$B$67 -> 0 | I67: =I66/$B$67 -> 0 | J67: =J66/$B$67 -> 0 | ... O67: =O66/$B$67 -> 318096.14 | S67: =S66/$B$67 -> 300.42413 | T67: =T66/$B$67 -> 114868.05 | V67: =V66/$B$67 -> 220900.09 | W67: =W66/$B$67 -> 176.72008 | X67: =X66/$B$67 -> 1539231.9 | Y67: =Y66/$B$67 -> 2977733.3 | Z67: =Z66/$B$67 -> 1673539.1 | AA67: =AA66/$B$67 -> 3175659.8
A68: Inflation rate | B68: 0 | C68: =C67+C67*$B$68 -> 0 | D68: =D67+D67*$B$68 -> 0 | E68: =E67+E67*$B$68 -> 0 | F68: =F67+F67*$B$68 -> 0 | G68: =G67+G67*$B$68 -> 0 | H68: =H67+H67*$B$68 -> 0 | I68: =I67+I67*$B$68 -> 0 | J68: =J67+J67*$B$68 -> 0 | ... O68: =O67+O67*$B$68 -> 318096.14 | T68: =T67+T67*$B$68 -> 114868.05 | V68: =V67+V67*$B$68 -> 220900.09 | X68: =X67+X67*$B$68 -> 1539231.9 | Y68: =Y67+Y67*$B$68 -> 2977733.3 | Z68: =Z67+Z67*$B$68 -> 1673539.1 | AA68: =AA67+AA67*$B$68 -> 3175659.8
I69: Med High | J69: =(J68+K68)/2 -> 0 | Z69: =(Z68+AA68)/2 -> 2424599.4 | AC69: Medium grade benchmark
Z70: =(AA68+Z69)/2 -> 2800129.6 | AC70: Medium to high grade benchmark
A71: sqmt to sqft | B71: 10.7639 | C71: =C68/$B$71 -> 0 | D71: =D68/$B$71 -> 0 | E71: =E68/$B$71 -> 0 | F71: =F68/$B$71 -> 0 | G71: =G68/$B$71 -> 0 | H71: =H68/$B$71 -> 0 | I71: =I68/$B$71 -> 0 | J71: =J68/$B$71 -> 0 | ... R71: =R68/$B$71 -> 0 | T71: =T68/$B$71 -> 10671.601 | U71: =(T71+V71)/2 -> 15596.956 | V71: =V68/$B$71 -> 20522.31 | X71: =X68/$B$71 -> 142999.46 | Y71: =Y68/$B$71 -> 276640.74 | Z71: =Z68/$B$71 -> 155477.02 | AA71: =AA68/$B$71 -> 295028.73
P72: Med High | Q72: =(Q71+R71)/2 -> 0
A73: Local Consultant Rate | C73: ='Local consultant_Summary'!$E$73 -> 18.548459
C74: =C73/B67 -> 31217.953
A75: Inflation rate | B75: 0 | C75: =C74+C74*$B$68 -> 31217.953
...

Sheet Local consultant_Summary
C2: Key Project Information
C3: Project Name: | D3: Marsh Nigeria Ibadan Office Fit Out
C4: Project Address:
C5: MMC Entity: | D5: Marsh
C6: Floor Area sqft:
C7: Floor Area sqm:
C8: New HC:
C9: New Deskcount:
C10: Sharing Ratio:
C11: Capex Ref #: | D11: [UK Only]
C12: Seq Project Code: | D12: PMO to advise
C13: USD MMC FX rate: | D13: ='[2]2025 Fixed MMC FX Rates'!F95 -> 0.00059416
C15: Financial Summary: Local Currency NGN
E19: AM Capex Budget | G19: Capex Committed | I19: Capex + P&L Committed | K19: Capex Variance | M19: Variance %
Q20: Project Actual Rates Calculator (Local)
C21: Professional fees | E21: =(E23+E27)*10% -> 20958816 | G21: =[2]LocalCurrency_Detail!E4 -> 0 | I21: =[2]LocalCurrency_Detail!E4+[2]LocalCurrency_Detail!F4 -> 0 | K21: =G21-E21 -> -20958816 | M21: =IFERROR(K21/E21,0) -> -1 | R21: What | S21: per | T21: Rate
R22: Fit-out Works | S22: sqft | T22: =IFERROR(I23/D6,0) -> 0
C23: Fit out Works | E23: 1.3938816e+08 | G23: =[2]LocalCurrency_Detail!G4+[2]LocalCurrency_Detail!M4 -> 0 | I23: =[2]LocalCurrency_Detail!G4+[2]LocalCurrency_Detail!H4+[2]LocalCurrency_Detail!M4+[2]LocalCurrency_Detail!N4 -> 0 | K23: =G23-E23 -> -1.3938816e+08 | M23: =IFERROR(K23/E23,0) -> -1 | R23: (Construction+Cabling) | S23: sqft | T23: =IFERROR((I23-[2]LocalCurrency_Detail!$M$4-[2]LocalCurrency_Detail!$N$4)/$D$6,0) -> 0
R24: (Security) | S24: sqft | T24: =IFERROR((I23-[2]LocalCurrency_Detail!$G$4-[2]LocalCurrency_Detail!$H$4)/$D$6,0) -> 0
C25: AV/Equipment | G25: =[2]LocalCurrency_Detail!K4 -> 0 | I25: =[2]LocalCurrency_Detail!K4+[2]LocalCurrency_Detail!L4 -> 0 | K25: =G25-E25 -> 0 | M25: =IFERROR(K25/E25,0) -> 0 | R25: AV | S25: sqft | T25: =IFERROR($I$25/$D$6,0) -> 0
R26: Furniture | S26: sqft | T26: =IFERROR(I27/D6,0) -> 0
C27: Furniture | E27: 70200000 | G27: =[2]LocalCurrency_Detail!I4 -> 0 | I27: =[2]LocalCurrency_Detail!I4+[2]LocalCurrency_Detail!J4 -> 0 | K27: =G27-E27 -> -70200000 | M27: =IFERROR(K27/E27,0) -> -1 | R27: Furniture | S27: HC | T27: =IFERROR(I27/D8,0) -> 0
R28: Professional Fees | S28: % | T28: =G21/SUM(I23:I27) -> #DIV/0!
C29: Total D&C | E29: =SUM(E21:E27) -> 2.3054698e+08 | G29: =SUM(G21:G27) -> 0 | I29: =SUM(I21:I27) -> 0 | K29: =G29-E29 -> -2.3054698e+08 | M29: =IFERROR(K29/E29,0) -> -1 | R29: Total Cost | S29: sqft | T29: =IFERROR(I29/D6,0) -> 0
R30: Total Cost | S30: sqm | T30: =IFERROR(I29/D7,0) -> 0
C31: Legal (CAPEX) | I31: =G31 -> 0 | K31: =I31-E31 -> 0 | M31: =IFERROR(K31/E31,0) -> 0
C32: Broker (CAPEX) | I32: =G32 -> 0 | K32: =I32-E32 -> 0 | M32: =IFERROR(K32/E32,0) -> 0
C33: MMC Tech (5 years - CAPEX) | I33: =G33 -> 0 | K33: =I33-E33 -> 0 | M33: =IFERROR(K33/E33,0) -> 0
C35: Moves (P&L) | E35: 7745192.3 | G35: =[2]LocalCurrency_Detail!O4 -> 0 | I35: =[2]LocalCurrency_Detail!O4+[2]LocalCurrency_Detail!P4 -> 0 | K35: =I35-E35 -> -7745192.3 | M35: =IFERROR(K35/E35,0) -> -1
C36: MMC Tech (P&L) | E36: 0 | G36: 0 | I36: 0 | K36: =I36-E36 -> 0 | M36: =IFERROR(K36/E36,0) -> 0
C38: Total Capex | E38: =E29+E31+E32+E33 -> 2.3054698e+08 | G38: =G29+G31+G32+G33 -> 0 | I38: =SUM(I29)+I31+I32+I33+I35+I36 -> 0 | K38: =G38-E38 -> -2.3054698e+08 | M38: =IFERROR(K38/E38,0) -> -1
C40: Financial Summary: USD
E44: =E19 -> AM Capex Budget | G44: Capex Committed | I44: Capex + P&L Committed | K44: Variance | M44: Variance %
Q45: Project Actual Rates Calculator (USD)
C46: Professional fees | E46: =$D$13*E21 -> 12452.89 | G46: =$D$13*G21 -> 0 | I46: =$D$13*I21 -> 0 | K46: =G46-E46 -> -12452.89 | M46: =IFERROR(K46/E46,0) -> -1 | R46: What | S46: per | T46: Rate
R47: Fit-out Works | S47: sqft | T47: =T22*$D$13 -> 0
C48: Fit out Works | E48: =$D$13*E23 -> 82818.87 | G48: =$D$13*G23 -> 0 | I48: =$D$13*I23 -> 0 | K48: =G48-E48 -> -82818.87 | M48: =IFERROR(K48/E48,0) -> -1 | R48: (Construction+Cabling) | S48: sqft | T48: =T23*$D$13 -> 0
R49: (Security) | S49: sqft | T49: =T24*$D$13 -> 0
C50: AV/Equipment | E50: =$D$13*E25 -> 0 | G50: =$D$13*G25 -> 0 | I50: =$D$13*I25 -> 0 | K50: =G50-E50 -> 0 | M50: =IFERROR(K50/E50,0) -> 0 | R50: AV | S50: sqft | T50: =T25*$D$13 -> 0
R51: Furniture | S51: sqft | T51: =T26*$D$13 -> 0
...

Sheet 2025 FX Rates
A2: MARSH MCLENNAN
A3: FOREIGN EXCHANGE RATE SUMMARY REPORT
A4: 2025 BUDGET
D6: 1st Pass* | F6: 2nd Pass | H6: Variance
C7: CURR | D7: BUDGET | F7: BUDGET | H7: 2nd Pass vs 1st Pass
A8: COUNTRY | B8: CURRENCY | C8: CODE | D8: RATE | F8: RATE | H8: $ | I8: %
A9: ALBANIA | B9: LEK | C9: ALL | D9: 0.01053408 | F9: 0.010755 | H9: =(F9-D9) -> 0.00022092 | I9: =H9/D9 -> 0.020971931
A10: ALGERIA | B10: DINAR | C10: DZD | D10: 0.00746088 | F10: 0.0075002 | H10: =(F10-D10) -> 3.932e-05 | I10: =H10/D10 -> 0.0052701558
A11: ANGOLA | B11: KWANZA | C11: AOA | D11: 0.00119768 | F11: 0.00108685 | H11: =(F11-D11) -> -0.00011083 | I11: =H11/D11 -> -0.092537239
A12: ARGENTINA | B12: PESO | C12: ARS | D12: 0.00071429 | F12: 0.00071429 | H12: =(F12-D12) -> 0 | I12: =H12/D12 -> 0
A13: ARUBA | B13: FLORIN | C13: AWG | D13: 0.55865922 | F13: 0.55865922 | H13: =(F13-D13) -> 0 | I13: =H13/D13 -> 0
A14: AUSTRALIA | B14: DOLLAR | C14: AUD | D14: 0.66 | F14: 0.65 | H14: =(F14-D14) -> -0.01 | I14: =H14/D14 -> -0.015151515
A15: AZERBAIJAN | B15: AZERBAIJAN | C15: AZN | D15: 0.58899753 | F15: 0.58820069 | H15: =(F15-D15) -> -0.00079684 | I15: =H15/D15 -> -0.0013528749
A16: BAHAMAS | B16: DOLLAR | C16: BSD | D16: 1 | F16: 1 | H16: =(F16-D16) -> 0 | I16: =H16/D16 -> 0
A17: BAHRAIN | B17: DINAR | C17: BHD | D17: 2.6525902 | F17: 2.6528014 | H17: =(F17-D17) -> 0.00021111 | I17: =H17/D17 -> 7.9586359e-05
A18: BANGLADESH | B18: TAKA | C18: BDT | D18: 0.00904425 | F18: 0.0083649 | H18: =(F18-D18) -> -0.00067935 | I18: =H18/D18 -> -0.075114023
A19: BARBADOS | B19: DOLLAR | C19: BBD | D19: 0.5 | F19: 0.5 | H19: =(F19-D19) -> 0 | I19: =H19/D19 -> 0
A20: BELARUS | B20: RUBLE | C20: BYR | D20: 3.044e-05 | F20: 3.065e-05 | H20: =(F20-D20) -> 2.1e-07 | I20: =H20/D20 -> 0.0068988173
... A145: ZIMBABWE | B145: DOLLAR | C145: ZWL | D145: 0.00017233 | F145: 2.763e-05 | H145: =(F145-D145) -> -0.0001447 | I145: =H145/D145 -> -0.83966808
A147: *Based on 2024 Budget Rates
