Workbook

Sheet FITOUT
E1: FIT OUT $/M2 | O1: FIT OUT $/SQFT | Y1: LOCATION FACTOR
E2: Activity | H2: Team | K2: Event | O2: Activity | R2: Team | U2: Event | Y2: EMEA | Z2: AMERICA | AA2: APAC
E3: Low | F3: Medium | G3: High | H3: Low | I3: Medium | J3: High | K3: Low | L3: Medium | M3: High | O3: Low | P3: Medium | Q3: High | R3: Low | S3: Medium | T3: High | U3: Low | V3: Medium | W3: High | Y3: =O138 -> 145.42387 | Z3: =O25 -> 213.86534 | AA3: =O133 -> 122.9244
B4: COUNTRY | C4: CITY | D4: REGION
B5: United States | C5: Cincinnati | D5: AMERICAS | E5: 1812.7573 | F5: 2640.9279 | G5: 3159.8936 | H5: 1744.1546 | I5: 2478.8513 | J5: 2933.1367 | K5: 1826.7708 | L5: 2431.3083 | M5: 2969.2193 | O5: 168.4093 | P5: 245.34823 | Q5: 293.56133 | R5: 162.03595 | S5: 230.29095 | T5: 272.4951 | U5: 169.71118 | V5: 225.87409 | W5: 275.84725 | Z5: =O5/$Z$3 -> 0.78745484
B6: United States | C6: Charlotte | D6: AMERICAS | E6: 1693.3113 | F6: 2466.1542 | G6: 2950.4485 | H6: 1671.2387 | I6: 2376.9915 | J6: 2805.8961 | K6: 1972.5798 | L6: 2620.993 | M6: 3225.4336 | O6: 157.31249 | P6: 229.11135 | Q6: 274.10341 | R6: 155.26189 | S6: 220.82794 | T6: 260.67415 | U6: 183.25717 | V6: 243.49624 | W6: 299.65015 | Z6: =O6/$Z$3 -> 0.73556794
B7: United States | C7: Charleston | D7: AMERICAS | E7: 1693.3113 | F7: 2466.1542 | G7: 2950.4485 | H7: 1671.2387 | I7: 2376.9915 | J7: 2805.8961 | K7: 1972.5798 | L7: 2620.993 | M7: 3225.4336 | O7: 157.31249 | P7: 229.11135 | Q7: 274.10341 | R7: 155.26189 | S7: 220.82794 | T7: 260.67415 | U7: 183.25717 | V7: 243.49624 | W7: 299.65015 | Z7: =O7/$Z$3 -> 0.73556794
B8: United States | C8: Chicago | D8: AMERICAS | E8: 2218.4928 | F8: 3234.6057 | G8: 3871.3426 | H8: 2189.4729 | I8: 3117.3779 | J8: 3681.2884 | K8: 2585.6683 | L8: 3438.183 | M8: 4232.8861 | O8: 206.10305 | P8: 300.50225 | Q8: 359.65657 | R8: 203.40703 | S8: 289.61153 | T8: 342.0001 | U8: 240.21449 | V8: 319.41505 | W8: 393.24479 | Z8: =O8/$Z$3 -> 0.96370477
B9: United States | C9: Cleveland | D9: AMERICAS | E9: 1758.2914 | F9: 2556.5694 | G9: 3071.177 | H9: 1711.5122 | I9: 2430.6211 | J9: 2880.7703 | K9: 1940.2859 | L9: 2568.7384 | M9: 3179.7703 | O9: 163.34929 | P9: 237.51113 | Q9: 285.31936 | R9: 159.00339 | S9: 225.81025 | T9: 267.63014 | U9: 180.25699 | V9: 238.64167 | W9: 295.40792 | Z9: =O9/$Z$3 -> 0.76379505
B10: United States | C10: Boston | D10: AMERICAS | E10: 2159.7181 | F10: 3148.6057 | G10: 3768.2819 | H10: 2131.4759 | I10: 3034.5182 | J10: 3583.3207 | K10: 2506.1422 | L10: 3309.3118 | M10: 4058.2223 | O10: 200.64274 | P10: 292.51266 | Q10: 350.082 | R10: 198.01898 | S10: 281.91367 | T10: 332.89868 | U10: 232.82634 | V10: 307.44262 | W10: 377.01812 | Z10: =O10/$Z$3 -> 0.93817325
B11: United States | C11: Baltimore | D11: AMERICAS | E11: 1765.812 | F11: 2572.7882 | G11: 3092.4575 | H11: 1745.5316 | I11: 2479.1447 | J11: 2938.3734 | K11: 2151.8588 | L11: 2859.9547 | M11: 3520.0318 | O11: 164.04797 | P11: 239.0179 | Q11: 287.29636 | R11: 162.16387 | S11: 230.31821 | T11: 272.9816 | U11: 199.9126 | V11: 265.69633 | W11: 327.019 | Z11: =O11/$Z$3 -> 0.76706198
B12: United States | C12: Columbus | D12: AMERICAS | E12: 1717.8081 | F12: 2497.4426 | G12: 3000.0318 | H12: 1672.1208 | I12: 2374.4356 | J12: 2814.0716 | K12: 1895.552 | L12: 2509.3277 | M12: 3106.0885 | O12: 159.58829 | P12: 232.01812 | Q12: 278.70981 | R12: 155.34384 | S12: 220.59049 | T12: 261.43368 | U12: 176.10111 | V12: 233.12227 | W12: 288.56272 | Z12: =O12/$Z$3 -> 0.74620924
B13: United States | C13: Austin | D13: AMERICAS | E13: 1612.2665 | F13: 2322.8329 | G13: 2795.9229 | H13: 1649.271 | I13: 2341.8429 | J13: 2775.3809 | K13: 1784.6753 | L13: 2384.5977 | M13: 2928.0398 | O13: 149.78324 | P13: 215.79648 | Q13: 259.74763 | R13: 153.22104 | S13: 217.56255 | T13: 257.83922 | U13: 165.80041 | V13: 221.53457 | W13: 272.02158 | Z13: =O13/$Z$3 -> 0.70036241
B14: United States | C14: Atlanta | D14: AMERICAS | E14: 1701.2466 | F14: 2518.81 | G14: 3020.0353 | H14: 1412.2452 | I14: 2014.3615 | J14: 2391.2755 | K14: 1877.2511 | L14: 2485.0229 | M14: 3075.9458 | O14: 158.0497 | P14: 234.00321 | Q14: 280.56818 | R14: 131.2008 | S14: 187.13879 | T14: 222.15495 | U14: 174.40092 | V14: 230.8643 | W14: 285.76239 | Z14: =O14/$Z$3 -> 0.73901503
B15: United States | C15: Dallas | D15: AMERICAS | E15: 1620.2795 | F15: 2355 | G15: 2828.6365 | H15: 1577.2248 | I15: 2239.0796 | J15: 2653.3894 | K15: 1787.7837 | L15: 2366.2004 | M15: 2928.5833 | O15: 150.52766 | P15: 218.78488 | Q15: 262.78679 | R15: 146.52778 | S15: 208.01561 | T15: 246.50593 | U15: 166.08919 | V15: 219.82542 | W15: 272.07208 | Z15: =O15/$Z$3 -> 0.70384319
B16: United States | C16: Denver | D16: AMERICAS | E16: 1730.6892 | F16: 2516.2556 | G16: 3022.6688 | H16: 1684.6544 | I16: 2392.3128 | J16: 2835.2939 | K16: 1909.7852 | L16: 2528.2312 | M16: 3129.5326 | O16: 160.78498 | P16: 233.76589 | Q16: 280.81284 | R16: 156.50824 | S16: 222.25132 | T16: vh | U16: 177.42341 | V16: 234.87846 | W16: 290.74072 | Z16: =O16/$Z$3 -> 0.75180476
B17: United States | C17: Detroit | D17: AMERICAS | E17: 1817.177 | F17: 2642.5724 | G17: 3174.6614 | H17: 1768.8081 | I17: 2512.3456 | J17: 2977.7862 | K17: 2005.3531 | L17: 2655.1551 | M17: 3286.9428 | O17: 168.8199 | P17: 245.50101 | Q17: 294.93329 | R17: 164.32631 | S17: 233.40264 | T17: 276.64314 | U17: 186.30188 | V17: 246.66998 | W17: 305.36449 | Z17: =O17/$Z$3 -> 0.78937474
B18: United States | C18: Houston | D18: AMERICAS | E18: 1609.2392 | F18: 2338.8752 | G18: 2809.2327 | H18: 1566.4818 | I18: 2223.7563 | J18: 2635.1989 | K18: 1775.5838 | L18: 2349.9975 | M18: 2908.4883 | O18: 149.502 | P18: 217.28685 | Q18: 260.98414 | R18: 145.52974 | S18: 206.59204 | T18: 244.816 | U18: 164.95579 | V18: 218.32014 | W18: 270.20521 | Z18: =O18/$Z$3 -> 0.69904734
B19: United States | C19: Indianapolis | D19: AMERICAS | E19: 1710.4475 | F19: 2486.6922 | G19: 2987.0965 | H19: 1664.9592 | I19: 2364.2203 | J19: 2801.9448 | K19: 1887.4182 | L19: 2498.5256 | M19: 3092.6922 | O19: 158.90448 | P19: 231.01938 | Q19: 277.50808 | R19: 154.67851 | S19: 219.64146 | T19: 260.30707 | U19: 175.34546 | V19: 232.11874 | W19: 287.31817 | Z19: =O19/$Z$3 -> 0.74301186
B20: United States | C20: Kansas City | D20: AMERICAS | E20: 1796.9354 | F20: 2613.0085 | G20: 3139.089 | H20: 1749.1124 | I20: 2484.2521 | J20: 2944.4366 | K20: 1982.9861 | L20: 2625.4495 | M20: 3250.1024 | O20: 166.9394 | P20: 242.75445 | Q20: 291.62854 | R20: 162.49654 | S20: 230.7927 | T20: 273.54489 | U20: 184.22394 | V20: 243.91026 | W20: 301.94194 | Z20: =O20/$Z$3 -> 0.78058184
B21: United States | C21: Los Angeles | D21: AMERICAS | E21: 2120.8026 | F21: 3086.0234 | G21: 3708.2516 | H21: 2064.2402 | I21: 2933.7355 | J21: 3478.0249 | K21: 2340.8573 | L21: 3100.7379 | M21: 3839.554 | O21: 197.0274 | P21: 286.69862 | Q21: 344.50504 | R21: 191.77263 | S21: 272.55072 | T21: 323.11645 | U21: 217.47099 | V21: 288.06564 | W21: 356.70333 | Z21: =O21/$Z$3 -> 0.92126852
B22: United States | C22: Miami | D22: AMERICAS | E22: 1660.7633 | F22: 2414.1268 | G22: 2899.7817 | H22: 1616.6156 | I22: 2295.2645 | J22: 2720.0875 | K22: 1832.5177 | L22: 2425.6121 | M22: 3002.2645 | O22: 154.2887 | P22: 224.27789 | Q22: 269.39634 | R22: 150.18728 | S22: 213.23532 | T22: 252.70234 | U22: 170.24508 | V22: 225.34491 | W22: 278.91723 | Z22: =O22/$Z$3 -> 0.72142922
B23: United States | C23: Minneapolis | D23: AMERICAS | E23: 1951.5077 | F23: 2838.7658 | G23: 3410.735 | H23: 1899.5142 | I23: 2698.7782 | J23: 3199.1034 | K23: 2153.7882 | L23: 2852.2919 | M23: 3531.4316 | O23: 181.29952 | P23: 263.72783 | Q23: 316.86507 | R23: 176.46921 | S23: 250.72266 | T23: 297.20402 | U23: 200.09184 | V23: 264.98443 | W23: 328.07806 | Z23: =O23/$Z$3 -> 0.84772747
B24: United States | C24: Nashville | D24: AMERICAS | E24: 1655.2432 | F24: 2406.0641 | G24: 2890.0806 | H24: 1611.2447 | I24: 2287.6032 | J24: 2710.9925 | K24: 1826.4177 | L24: 2417.5107 | M24: 2992.2173 | O24: 153.77587 | P24: 223.52885 | Q24: 268.49508 | R24: 149.68831 | S24: 212.52356 | T24: 251.8574 | U24: 169.67838 | V24: 224.59226 | W24: 277.98382 | Z24: =O24/$Z$3 -> 0.71903129
B25: United States | C25: New York | D25: AMERICAS | E25: 2302.0461 | F25: 3357.5815 | G25: 4037.3144 | H25: 2275.5186 | I25: 3235.094 | J25: 3835.7708 | K25: 2619.6763 | L25: 3646.4286 | M25: 4441.179 | O25: 213.86534 | P25: 311.92699 | Q25: 375.07572 | R25: 211.40088 | S25: 300.54762 | T25: 356.35186 | U25: 243.37391 | V25: 338.76155 | W25: 412.59567 | Z25: =O25/$Z$3 -> 1
B26: United States | C26: Newark | D26: AMERICAS | E26: 2130.0035 | F26: 3099.462 | G26: 3724.4207 | H26: 2073.1924 | I26: 2946.5052 | J26: 3493.183 | K26: 2351.0239 | L26: 3114.2407 | M26: 3856.2999 | O26: 197.88219 | P26: 287.9471 | Q26: 346.00719 | R26: 192.60431 | S26: 273.73706 | T26: 324.52468 | U26: 218.41549 | V26: 289.32007 | W26: 358.25906 | Z26: =O26/$Z$3 -> 0.92526535
B27: United States | C27: Oakland | D27: AMERICAS | E27: 2210.9702 | F27: 3217.7156 | G27: 3866.7116 | H27: 2151.9741 | I27: 3058.8767 | J27: 3626.5798 | K27: 2440.4913 | L27: 3233.0627 | M27: 4003.6624 | O27: 205.40418 | P27: 298.93313 | Q27: 359.22634 | R27: 199.92331 | S27: 284.17663 | T27: 336.91755 | U27: 226.72722 | V27: 300.3589 | W27: 371.94938 | Z27: =O27/$Z$3 -> 0.96043697
B28: United States | C28: Orlando | D28: AMERICAS | E28: 1662.6032 | F28: 2416.815 | G28: 2903.0154 | H28: 1618.4068 | I28: 2297.819 | J28: 2723.1188 | K28: 1834.5505 | L28: 2428.3128 | M28: 3005.6136 | O28: 154.45963 | P28: 224.52764 | Q28: 269.69676 | R28: 150.35368 | S28: 213.47263 | T28: 252.98396 | U28: 170.43393 | V28: 225.5958 | W28: 279.22837 | Z28: =O28/$Z$3 -> 0.72222845
... B44: United States | C44: Tulsa | D44: AMERICAS | E44: 1571.9712 | F44: 2289.0962 | G44: 2750.9043 | H44: 1553.9483 | I44: 2205.8792 | J44: 2613.9766 | K44: 1795.7379 | L44: 2493.3093 | M44: 3033.2591 | O44: 146.03972 | P44: 212.66226 | Q44: 255.56529 | R44: 144.36534 | S44: 204.93121 | T44: 242.8444 | U44: 166.82816 | V44: 231.63413 | W44: 281.7967 | Z44: =O44/$Z$3 -> 0.68285828
B45: Saint Kitts and Nevis | C45: Basseterre | D45: AMERICAS | E45: =O45*10.764 -> 1540.2208 | F45: =P45*10.764 -> 2238.0509 | G45: =Q45*10.764 -> 2687.9861 | H45: =R45*10.764 -> 1499.3176 | I45: =S45*10.764 -> 2127.9352 | J45: =T45*10.764 -> 2521.467 | K45: =U45*10.764 -> 1699.3127 | L45: =V45*10.764 -> 2248.7072 | M45: =W45*10.764 -> 2782.8169 | O45: 143.09 | P45: 207.92 | Q45: 249.72 | R45: 139.29 | S45: 197.69 | T45: 234.25 | U45: 157.87 | V45: 208.91 | W45: 258.53 | Z45: =O45/$Z$3 -> 0.66906587
B46: Puerto Rico | C46: San Juan | D46: AMERICAS | E46: =O46*10.764 -> 1684.1354 | F46: =P46*10.764 -> 2448.2718 | G46: =Q46*10.764 -> 2940.9401 | H46: =R46*10.764 -> 1639.3572 | I46: =S46*10.764 -> 2327.715 | J46: =T46*10.764 -> 2758.5979 | K46: =U46*10.764 -> 1858.4046 | L46: =V46*10.764 -> 2460.0046 | M46: =W46*10.764 -> 3044.8127 | O46: 156.46 | P46: 227.45 | Q46: 273.22 | R46: 152.3 | S46: 216.25 | T46: 256.28 | U46: 172.65 | V46: 228.54 | W46: 282.87 | Z46: =O46/$Z$3 -> 0.73158185
B47: Barbados | C47: Bridgetown | D47: AMERICAS | E47: =O47*10.764 -> 1630.3154 | F47: =P47*10.764 -> 2369.6946 | G47: =Q47*10.764 -> 2846.3245 | H47: =R47*10.764 -> 1587.0442 | I47: =S47*10.764 -> 2253.0128 | J47: =T47*10.764 -> 2669.9026 | K47: =U47*10.764 -> 1798.8797 | L47: =V47*10.764 -> 2380.8892 | M47: =W47*10.764 -> 2946.8603 | O47: 151.46 | P47: 220.15 | Q47: 264.43 | R47: 147.44 | S47: 209.31 | T47: 248.04 | U47: 167.12 | V47: 221.19 | W47: 273.77 | Z47: =O47/$Z$3 -> 0.70820265
B48: Saint Lucia | C48: Castries | D48: AMERICAS | E48: =O48*10.764 -> 1630.3154 | F48: =P48*10.764 -> 2369.6946 | G48: =Q48*10.764 -> 2846.3245 | H48: =R48*10.764 -> 1587.0442 | I48: =S48*10.764 -> 2253.0128 | J48: =T48*10.764 -> 2669.9026 | K48: =U48*10.764 -> 1798.8797 | L48: =V48*10.764 -> 2380.8892 | M48: =W48*10.764 -> 2946.8603 | O48: 151.46 | P48: 220.15 | Q48: 264.43 | R48: 147.44 | S48: 209.31 | T48: 248.04 | U48: 167.12 | V48: 221.19 | W48: 273.77 | Z48: =O48/$Z$3 -> 0.70820265
B49: Turks & Caicos Islands | C49: Cockburn Town | D49: AMERICAS | E49: =O49*10.764 -> 2018.0347 | F49: =P49*10.764 -> 2935.881 | G49: =Q49*10.764 -> 3527.5781 | H49: =R49*10.764 -> 1964.2147 | I49: =S49*10.764 -> 2791.1052 | J49: =T49*10.764 -> 3308.6383 | K49: =U49*10.764 -> 2227.2869 | L49: =V49*10.764 -> 2949.8742 | M49: =W49*10.764 -> 3652.4405 | O49: 187.48 | P49: 272.75 | Q49: 327.72 | R49: 182.48 | S49: 259.3 | T49: 307.38 | U49: 206.92 | V49: 274.05 | W49: 339.32 | Z49: =O49/$Z$3 -> 0.87662639
B50: Cayman Islands | C50: George Town | D50: AMERICAS | E50: =O50*10.764 -> 2020.7257 | F50: =P50*10.764 -> 2939.9713 | G50: =Q50*10.764 -> 3532.4219 | H50: =R50*10.764 -> 1966.9057 | I50: =S50*10.764 -> 2794.8726 | J50: =T50*10.764 -> 3313.2668 | K50: =U50*10.764 -> 2230.3008 | L50: =V50*10.764 -> 2953.9645 | M50: =W50*10.764 -> 3657.4996 | O50: 187.73 | P50: 273.13 | Q50: 328.17 | R50: 182.73 | S50: 259.65 | T50: 307.81 | U50: 207.2 | V50: 274.43 | W50: 339.79 | Z50: =O50/$Z$3 -> 0.87779535
B51: Saint Vincent The Grenadines | C51: Kingstontown | D51: AMERICAS | E51: =O51*10.764 -> 1073.6014 | F51: =P51*10.764 -> 1556.4744 | G51: =Q51*10.764 -> 1867.8769 | H51: =R51*10.764 -> 1045.292 | I51: =S51*10.764 -> 1480.2653 | J51: =T51*10.764 -> 1752.7021 | K51: =U51*10.764 -> 1183.7171 | L51: =V51*10.764 -> 1563.9016 | M51: =W51*10.764 -> 1933.5373 | O51: 99.74 | P51: 144.6 | Q51: 173.53 | R51: 97.11 | S51: 137.52 | T51: 162.83 | U51: 109.97 | V51: 145.29 | W51: 179.63 | Z51: =O51/$Z$3 -> 0.46636823
B52: Bahamas | C52: Nassau | D52: AMERICAS | E52: =O52*10.764 -> 2028.1529 | F52: =P52*10.764 -> 2950.7353 | G52: =Q52*10.764 -> 3545.4463 | H52: =R52*10.764 -> 1974.1176 | I52: =S52*10.764 -> 2805.0984 | J52: =T52*10.764 -> 3325.3225 | K52: =U52*10.764 -> 2238.4814 | L52: =V52*10.764 -> 2964.7285 | M52: =W52*10.764 -> 3670.9546 | O52: 188.42 | P52: 274.13 | Q52: 329.38 | R52: 183.4 | S52: 260.6 | T52: 308.93 | U52: 207.96 | V52: 275.43 | W52: 341.04 | Z52: =O52/$Z$3 -> 0.88102168
B53: St. Maarten | C53: Philipsburg | D53: AMERICAS | E53: =O53*10.764 -> 1693.1772 | F53: =P53*10.764 -> 2461.5115 | G53: =Q53*10.764 -> 2956.7632 | H53: =R53*10.764 -> 1648.1837 | I53: =S53*10.764 -> 2340.3089 | J53: =T53*10.764 -> 2773.5599 | K53: =U53*10.764 -> 1868.3075 | L53: =V53*10.764 -> 2473.2443 | M53: =W53*10.764 -> 3061.2816 | O53: 157.3 | P53: 228.68 | Q53: 274.69 | R53: 153.12 | S53: 217.42 | T53: 257.67 | U53: 173.57 | V53: 229.77 | W53: 284.4 | Z53: =O53/$Z$3 -> 0.73550955
B54: Trinidad Tobago | C54: Port of Spain | D54: AMERICAS | E54: =O54*10.764 -> 1777.4593 | F54: =P54*10.764 -> 2584.544 | G54: =Q54*10.764 -> 3104.8758 | H54: =R54*10.764 -> 1730.2054 | I54: =S54*10.764 -> 2457.2059 | J54: =T54*10.764 -> 2912.4155 | K54: =U54*10.764 -> 1961.5237 | L54: =V54*10.764 -> 2596.9226 | M54: =W54*10.764 -> 3214.6686 | O54: 165.13 | P54: 240.11 | Q54: 288.45 | R54: 160.74 | S54: 228.28 | T54: 270.57 | U54: 182.23 | V54: 241.26 | W54: 298.65 | Z54: =O54/$Z$3 -> 0.77212138
B55: British Virgin Islands | C55: Road Town | D55: AMERICAS | E55: =O55*10.764 -> 1844.7343 | F55: =P55*10.764 -> 2682.8194 | G55: =Q55*10.764 -> 3223.0645 | H55: =R55*10.764 -> 1795.6505 | I55: =S55*10.764 -> 2550.6374 | J55: =T55*10.764 -> 3023.177 | K55: =U55*10.764 -> 2035.7953 | L55: =V55*10.764 -> 2695.6285 | M55: =W55*10.764 -> 3337.0553 | O55: 171.38 | P55: 249.24 | Q55: 299.43 | R55: 166.82 | S55: 236.96 | T55: 280.86 | U55: 189.13 | V55: 250.43 | W55: 310.02 | Z55: =O55/$Z$3 -> 0.80134537
...

Sheet FURNITURE
A1: a | E1: FURNITURE $/M2 | O1: FURNITURE $/SQFT | Y1: LOCATION FACTOR
E2: Activity | H2: Team | K2: Event | O2: Activity | R2: Team | U2: Event | Y2: EMEA | Z2: AMERICA | AA2: APAC
E3: Low | F3: Medium | G3: High | H3: Low | I3: Medium | J3: High | K3: Low | L3: Medium | M3: High | O3: Low | P3: Medium | Q3: High | R3: Low | S3: Medium | T3: High | U3: Low | V3: Medium | W3: High | Y3: 145.42387 | Z3: 213.86534 | AA3: 153.6541
B4: COUNTRY | C4: CITY | D4: REGION
B5: United States | C5: Cincinnati | D5: AMERICAS | E5: =238.73*$Z5 -> 187.98909 | F5: =315.46*Z5 -> 248.4105 | G5: =365.27*Z5 -> 287.63363 | H5: =191.35*Z5 -> 150.67948 | I5: =307.57*Z5 -> 242.19749 | J5: =368.13*Z5 -> 289.88575 | K5: =179*Z5 -> 140.95442 | L5: =252.87*Z5 -> 199.12371 | M5: =276.8*Z5 -> 217.9675 | O5: =22.18*$O5 -> #NUM! | P5: =29.31*$O5 -> #NUM! | Q5: =33.93*$O5 -> #NUM! | R5: =17.78*$O5 -> #NUM! | S5: =28.57*$O5 -> #NUM! | T5: =34.2*$O5 -> #NUM! | U5: =16.63*$O5 -> #NUM! | V5: =23.49*$O5 -> #NUM! | W5: =25.71*$O5 -> #NUM! | Z5: 0.78745484
B6: United States | C6: Charlotte | D6: AMERICAS | E6: =238.73*$Z6 -> 175.60213 | F6: =315.46*Z6 -> 232.04226 | G6: =365.27*Z6 -> 268.6809 | H6: =191.35*Z6 -> 140.75092 | I6: =307.57*Z6 -> 226.23863 | J6: =368.13*Z6 -> 270.78462 | K6: =179*Z6 -> 131.66666 | L6: =252.87*Z6 -> 186.00306 | M6: =276.8*Z6 -> 203.60521 | O6: =22.18*$O6 -> #NUM! | P6: =29.31*$O6 -> #NUM! | Q6: =33.93*$O6 -> #NUM! | R6: =17.78*$O6 -> #NUM! | S6: =28.57*$O6 -> #NUM! | T6: =34.2*$O6 -> #NUM! | U6: =16.63*$O6 -> #NUM! | V6: =23.49*$O6 -> #NUM! | W6: =25.71*$O6 -> #NUM! | Z6: 0.73556794
B7: United States | C7: Charleston | D7: AMERICAS | E7: =238.73*$Z7 -> 175.60213 | F7: =315.46*Z7 -> 232.04226 | G7: =365.27*Z7 -> 268.6809 | H7: =191.35*Z7 -> 140.75092 | I7: =307.57*Z7 -> 226.23863 | J7: =368.13*Z7 -> 270.78462 | K7: =179*Z7 -> 131.66666 | L7: =252.87*Z7 -> 186.00306 | M7: =276.8*Z7 -> 203.60521 | O7: =22.18*$O7 -> #NUM! | P7: =29.31*$O7 -> #NUM! | Q7: =33.93*$O7 -> #NUM! | R7: =17.78*$O7 -> #NUM! | S7: =28.57*$O7 -> #NUM! | T7: =34.2*$O7 -> #NUM! | U7: =16.63*$O7 -> #NUM! | V7: =23.49*$O7 -> #NUM! | W7: =25.71*$O7 -> #NUM! | Z7: 0.73556794
B8: United States | C8: Chicago | D8: AMERICAS | E8: =238.73*$Z8 -> 230.06524 | F8: =315.46*Z8 -> 304.01031 | G8: =365.27*Z8 -> 352.01244 | H8: =191.35*Z8 -> 184.40491 | I8: =307.57*Z8 -> 296.40668 | J8: =368.13*Z8 -> 354.76864 | K8: =179*Z8 -> 172.50315 | L8: =252.87*Z8 -> 243.69203 | M8: =276.8*Z8 -> 266.75348 | O8: =22.18*$O8 -> #NUM! | P8: =29.31*$O8 -> #NUM! | Q8: =33.93*$O8 -> #NUM! | R8: =17.78*$O8 -> #NUM! | S8: =28.57*$O8 -> #NUM! | T8: =34.2*$O8 -> #NUM! | U8: =16.63*$O8 -> #NUM! | V8: =23.49*$O8 -> #NUM! | W8: =25.71*$O8 -> #NUM! | Z8: 0.96370477
B9: United States | C9: Cleveland | D9: AMERICAS | E9: =238.73*$Z9 -> 182.34079 | F9: =315.46*Z9 -> 240.94679 | G9: =365.27*Z9 -> 278.99142 | H9: =191.35*Z9 -> 146.15218 | I9: =307.57*Z9 -> 234.92044 | J9: =368.13*Z9 -> 281.17587 | K9: =179*Z9 -> 136.71931 | L9: =252.87*Z9 -> 193.14085 | M9: =276.8*Z9 -> 211.41847 | O9: =22.18*$O9 -> #NUM! | P9: =29.31*$O9 -> #NUM! | Q9: =33.93*$O9 -> #NUM! | R9: =17.78*$O9 -> #NUM! | S9: =28.57*$O9 -> #NUM! | T9: =34.2*$O9 -> #NUM! | U9: =16.63*$O9 -> #NUM! | V9: =23.49*$O9 -> #NUM! | W9: =25.71*$O9 -> #NUM! | Z9: 0.76379505
B10: United States | C10: Boston | D10: AMERICAS | E10: =238.73*$Z10 -> 223.9701 | F10: =315.46*Z10 -> 295.95613 | G10: =365.27*Z10 -> 342.68654 | H10: =191.35*Z10 -> 179.51945 | I10: =307.57*Z10 -> 288.55395 | J10: =368.13*Z10 -> 345.36972 | K10: =179*Z10 -> 167.93301 | L10: =252.87*Z10 -> 237.23587 | M10: =276.8*Z10 -> 259.68636 | O10: =22.18*$O10 -> #NUM! | P10: =29.31*$O10 -> #NUM! | Q10: =33.93*$O10 -> #NUM! | R10: =17.78*$O10 -> #NUM! | S10: =28.57*$O10 -> #NUM! | T10: =34.2*$O10 -> #NUM! | U10: =16.63*$O10 -> #NUM! | V10: =23.49*$O10 -> #NUM! | W10: =25.71*$O10 -> #NUM! | Z10: 0.93817325
B11: United States | C11: Baltimore | D11: AMERICAS | E11: =238.73*$Z11 -> 183.12071 | F11: =315.46*Z11 -> 241.97737 | G11: =365.27*Z11 -> 280.18473 | H11: =191.35*Z11 -> 146.77731 | I11: =307.57*Z11 -> 235.92525 | J11: =368.13*Z11 -> 282.37853 | K11: =179*Z11 -> 137.3041 | L11: =252.87*Z11 -> 193.96696 | M11: =276.8*Z11 -> 212.32276 | O11: =22.18*$O11 -> #NUM! | P11: =29.31*$O11 -> #NUM! | Q11: =33.93*$O11 -> #NUM! | R11: =17.78*$O11 -> #NUM! | S11: =28.57*$O11 -> #NUM! | T11: =34.2*$O11 -> #NUM! | U11: =16.63*$O11 -> #NUM! | V11: =23.49*$O11 -> #NUM! | W11: =25.71*$O11 -> #NUM! | Z11: 0.76706198
B12: United States | C12: Columbus | D12: AMERICAS | E12: =238.73*$Z12 -> 178.14253 | F12: =315.46*Z12 -> 235.39917 | G12: =365.27*Z12 -> 272.56785 | H12: =191.35*Z12 -> 142.78714 | I12: =307.57*Z12 -> 229.51158 | J12: =368.13*Z12 -> 274.70201 | K12: =179*Z12 -> 133.57145 | L12: =252.87*Z12 -> 188.69393 | M12: =276.8*Z12 -> 206.55072 | O12: =22.18*$O12 -> #NUM! | P12: =29.31*$O12 -> #NUM! | Q12: =33.93*$O12 -> #NUM! | R12: =17.78*$O12 -> #NUM! | S12: =28.57*$O12 -> #NUM! | T12: =34.2*$O12 -> #NUM! | U12: =16.63*$O12 -> #NUM! | V12: =23.49*$O12 -> #NUM! | W12: =25.71*$O12 -> #NUM! | Z12: 0.74620924
B13: United States | C13: Austin | D13: AMERICAS | E13: =238.73*$Z13 -> 167.19752 | F13: =315.46*Z13 -> 220.93632 | G13: =365.27*Z13 -> 255.82138 | H13: =191.35*Z13 -> 134.01435 | I13: =307.57*Z13 -> 215.41047 | J13: =368.13*Z13 -> 257.82441 | K13: =179*Z13 -> 125.36487 | L13: =252.87*Z13 -> 177.10064 | M13: =276.8*Z13 -> 193.86031 | O13: =22.18*$O13 -> #NUM! | P13: =29.31*$O13 -> #NUM! | Q13: =33.93*$O13 -> #NUM! | R13: =17.78*$O13 -> #NUM! | S13: =28.57*$O13 -> #NUM! | T13: =34.2*$O13 -> #NUM! | U13: =16.63*$O13 -> #NUM! | V13: =23.49*$O13 -> #NUM! | W13: =25.71*$O13 -> #NUM! | Z13: 0.70036241
B14: United States | C14: Atlanta | D14: AMERICAS | E14: =238.73*$Z14 -> 176.42506 | F14: =315.46*Z14 -> 233.12968 | G14: =365.27*Z14 -> 269.94002 | H14: =191.35*Z14 -> 141.41053 | I14: =307.57*Z14 -> 227.29885 | J14: =368.13*Z14 -> 272.0536 | K14: =179*Z14 -> 132.28369 | L14: =252.87*Z14 -> 186.87473 | M14: =276.8*Z14 -> 204.55936 | O14: =22.18*$O14 -> #NUM! | P14: =29.31*$O14 -> #NUM! | Q14: =33.93*$O14 -> #NUM! | R14: =17.78*$O14 -> #NUM! | S14: =28.57*$O14 -> #NUM! | T14: =34.2*$O14 -> #NUM! | U14: =16.63*$O14 -> #NUM! | V14: =23.49*$O14 -> #NUM! | W14: =25.71*$O14 -> #NUM! | Z14: 0.73901503
B15: United States | C15: Dallas | D15: AMERICAS | E15: =238.73*$Z15 -> 168.02849 | F15: =315.46*Z15 -> 222.03437 | G15: =365.27*Z15 -> 257.0928 | H15: =191.35*Z15 -> 134.68039 | I15: =307.57*Z15 -> 216.48105 | J15: =368.13*Z15 -> 259.10579 | K15: =179*Z15 -> 125.98793 | L15: =252.87*Z15 -> 177.98083 | M15: =276.8*Z15 -> 194.8238 | O15: =22.18*$O15 -> #NUM! | P15: =29.31*$O15 -> #NUM! | Q15: =33.93*$O15 -> #NUM! | R15: =17.78*$O15 -> #NUM! | S15: =28.57*$O15 -> #NUM! | T15: =34.2*$O15 -> #NUM! | U15: =16.63*$O15 -> #NUM! | V15: =23.49*$O15 -> #NUM! | W15: =25.71*$O15 -> #NUM! | Z15: 0.70384319
B16: United States | C16: Denver | D16: AMERICAS | E16: =238.73*$Z16 -> 179.47835 | F16: =315.46*Z16 -> 237.16433 | G16: =365.27*Z16 -> 274.61173 | H16: =191.35*Z16 -> 143.85784 | I16: =307.57*Z16 -> 231.23259 | J16: =368.13*Z16 -> 276.76189 | K16: =179*Z16 -> 134.57305 | L16: =252.87*Z16 -> 190.10887 | M16: =276.8*Z16 -> 208.09956 | O16: =22.18*$O16 -> #NUM! | P16: =29.31*$O16 -> #NUM! | Q16: =33.93*$O16 -> #NUM! | R16: =17.78*$O16 -> #NUM! | S16: =28.57*$O16 -> #NUM! | T16: =34.2*$O16 -> #NUM! | U16: =16.63*$O16 -> #NUM! | V16: =23.49*$O16 -> #NUM! | W16: =25.71*$O16 -> #NUM! | Z16: 0.75180476
... B67: Mexico | C67: Queretaro | D67: AMERICAS | E67: =238.73*$Z67 -> 115.63473 | F67: =315.46*Z67 -> 152.80079 | G67: =365.27*Z67 -> 176.92748 | H67: =191.35*Z67 -> 92.685066 | I67: =307.57*Z67 -> 148.97907 | J67: =368.13*Z67 -> 178.3128 | K67: =179*Z67 -> 86.703041 | L67: =252.87*Z67 -> 122.48379 | M67: =276.8*Z67 -> 134.07487 | O67: =22.18*$O67 -> #NUM! | P67: =29.31*$O67 -> #NUM! | Q67: =33.93*$O67 -> #NUM! | R67: =17.78*$O67 -> #NUM! | S67: =28.57*$O67 -> #NUM! | T67: =34.2*$O67 -> #NUM! | U67: =16.63*$O67 -> #NUM! | V67: =23.49*$O67 -> #NUM! | W67: =25.71*$O67 -> #NUM! | Z67: 0.48437453
B68: Panama | C68: Panama City | D68: AMERICAS | E68: =(221.26*$Y68)*1.08 -> 267.83037 | F68: =(310.41*$Y68)*1.08 -> 375.74449 | G68: =(364.87*$Y68)*1.08 -> 441.66713 | H68: =(176.83*$Y68)*1.08 -> 214.04883 | I68: =(308.58*$Y68)*1.08 -> 373.52932 | J68: =(453.13*$Y68)*1.08 -> 548.50392 | K68: =(207.98*$Y68)*1.08 -> 251.75522 | L68: =(233.85*$Y68)*1.08 -> 283.07029 | M68: =(280.64*$Y68)*1.08 -> 339.70856 | O68: =(20.56*$Y68)*1.08 -> 24.887429 | P68: =(28.84*$Y68)*1.08 -> 34.910187 | Q68: =(33.93*$Y68)*1.08 -> 41.07152 | R68: =(16.43*$Y68)*1.08 -> 19.888154 | S68: =(28.67*$Y68)*1.08 -> 34.704406 | T68: =(42.1*$Y68)*1.08 -> 50.961126 | U68: =(19.32*$Y68)*1.08 -> 23.386436 | V68: =(21.73*$Y68)*1.08 -> 26.303688 | W68: =(26.07*$Y68)*1.08 -> 31.557163 | Y68: 1.120813
B69: Austria | C69: Vienna | D69: EMEA | E69: =(221.26*$Y69)*1.08 -> 133.38384 | F69: =(310.41*$Y69)*1.08 -> 187.1268 | G69: =(364.87*$Y69)*1.08 -> 219.95734 | H69: =(176.83*$Y69)*1.08 -> 106.59976 | I69: =(308.58*$Y69)*1.08 -> 186.02361 | J69: =(453.13*$Y69)*1.08 -> 273.16378 | K69: =(207.98*$Y69)*1.08 -> 125.37815 | L69: =(233.85*$Y69)*1.08 -> 140.97356 | M69: =(280.64*$Y69)*1.08 -> 169.18033 | O69: =(20.56*$Y69)*1.08 -> 12.39434 | P69: =(28.84*$Y69)*1.08 -> 17.385835 | Q69: =(33.93*$Y69)*1.08 -> 20.454278 | R69: =(16.43*$Y69)*1.08 -> 9.9046209 | S69: =(28.67*$Y69)*1.08 -> 17.283352 | T69: =(42.1*$Y69)*1.08 -> 25.379461 | U69: =(19.32*$Y69)*1.08 -> 11.646821 | V69: =(21.73*$Y69)*1.08 -> 13.09966 | W69: =(26.07*$Y69)*1.08 -> 15.715975 | Y69: 0.55818291
B70: Belgium | C70: Brussels | D70: EMEA | E70: =(221.26*$Y70)*1.08 -> 139.41779 | F70: =(310.41*$Y70)*1.08 -> 195.59195 | G70: =(364.87*$Y70)*1.08 -> 229.90766 | H70: =(176.83*$Y70)*1.08 -> 111.42207 | I70: =(308.58*$Y70)*1.08 -> 194.43885 | J70: =(453.13*$Y70)*1.08 -> 285.52103 | K70: =(207.98*$Y70)*1.08 -> 131.04995 | L70: =(233.85*$Y70)*1.08 -> 147.35085 | M70: =(280.64*$Y70)*1.08 -> 176.83363 | O70: =(20.56*$Y70)*1.08 -> 12.955029 | P70: =(28.84*$Y70)*1.08 -> 18.172327 | Q70: =(33.93*$Y70)*1.08 -> 21.379578 | R70: =(16.43*$Y70)*1.08 -> 10.352681 | S70: =(28.67*$Y70)*1.08 -> 18.065208 | T70: =(42.1*$Y70)*1.08 -> 26.527564 | U70: =(19.32*$Y70)*1.08 -> 12.173695 | V70: =(21.73*$Y70)*1.08 -> 13.692256 | W70: =(26.07*$Y70)*1.08 -> 16.426926 | Y70: 0.58343372
B71: Botswana | C71: Gabarone | D71: EMEA | E71: =(221.26*$Y71)*1.08 -> 131.42881 | F71: =(310.41*$Y71)*1.08 -> 184.38406 | G71: =(364.87*$Y71)*1.08 -> 216.73339 | H71: =(176.83*$Y71)*1.08 -> 105.03732 | I71: =(308.58*$Y71)*1.08 -> 183.29704 | J71: =(453.13*$Y71)*1.08 -> 269.15998 | K71: =(207.98*$Y71)*1.08 -> 123.54047 | L71: =(233.85*$Y71)*1.08 -> 138.90729 | M71: =(280.64*$Y71)*1.08 -> 166.70063 | O71: =(20.56*$Y71)*1.08 -> 12.212675 | P71: =(28.84*$Y71)*1.08 -> 17.131008 | Q71: =(33.93*$Y71)*1.08 -> 20.154477 | R71: =(16.43*$Y71)*1.08 -> 9.7594476 | S71: =(28.67*$Y71)*1.08 -> 17.030028 | T71: =(42.1*$Y71)*1.08 -> 25.007471 | U71: =(19.32*$Y71)*1.08 -> 11.476112 | V71: =(21.73*$Y71)*1.08 -> 12.907657 | W71: =(26.07*$Y71)*1.08 -> 15.485624 | Y71: 0.55000156
B72: Bulgaria | C72: Sofia | D72: EMEA | E72: =(221.26*$Y72)*1.08 -> 147.66553 | F72: =(310.41*$Y72)*1.08 -> 207.16287 | G72: =(364.87*$Y72)*1.08 -> 243.50864 | H72: =(176.83*$Y72)*1.08 -> 118.01363 | I72: =(308.58*$Y72)*1.08 -> 205.94155 | J72: =(453.13*$Y72)*1.08 -> 302.412 | K72: =(207.98*$Y72)*1.08 -> 138.80266 | L72: =(233.85*$Y72)*1.08 -> 156.0679 | M72: =(280.64*$Y72)*1.08 -> 187.29483 | O72: =(20.56*$Y72)*1.08 -> 13.721428 | P72: =(28.84*$Y72)*1.08 -> 19.247373 | Q72: =(33.93*$Y72)*1.08 -> 22.644361 | R72: =(16.43*$Y72)*1.08 -> 10.96513 | S72: =(28.67*$Y72)*1.08 -> 19.133918 | T72: =(42.1*$Y72)*1.08 -> 28.096894 | U72: =(19.32*$Y72)*1.08 -> 12.893871 | V72: =(21.73*$Y72)*1.08 -> 14.502268 | W72: =(26.07*$Y72)*1.08 -> 17.398718 | Y72: 0.61794875
B73: Croatia | C73: Zagreb | D73: EMEA | E73: =(221.26*$Y73)*1.08 -> 161.5634 | F73: =(310.41*$Y73)*1.08 -> 226.66047 | G73: =(364.87*$Y73)*1.08 -> 266.427 | H73: =(176.83*$Y73)*1.08 -> 129.12075 | I73: =(308.58*$Y73)*1.08 -> 225.32421 | J73: =(453.13*$Y73)*1.08 -> 330.87419 | K73: =(207.98*$Y73)*1.08 -> 151.86638 | L73: =(233.85*$Y73)*1.08 -> 170.75658 | M73: =(280.64*$Y73)*1.08 -> 204.9225 | O73: =(20.56*$Y73)*1.08 -> 15.012851 | P73: =(28.84*$Y73)*1.08 -> 21.058883 | Q73: =(33.93*$Y73)*1.08 -> 24.775586 | R73: =(16.43*$Y73)*1.08 -> 11.997138 | S73: =(28.67*$Y73)*1.08 -> 20.93475 | T73: =(42.1*$Y73)*1.08 -> 30.741296 | U73: =(19.32*$Y73)*1.08 -> 14.107407 | V73: =(21.73*$Y73)*1.08 -> 15.867182 | W73: =(26.07*$Y73)*1.08 -> 19.036237 | Y73: 0.67610838
B74: Czech Republic | C74: Prague | D74: EMEA | E74: =(221.26*$Y74)*1.08 -> 77.055389 | F74: =(310.41*$Y74)*1.08 -> 108.10252 | G74: =(364.87*$Y74)*1.08 -> 127.06861 | H74: =(176.83*$Y74)*1.08 -> 61.582321 | I74: =(308.58*$Y74)*1.08 -> 107.46521 | J74: =(453.13*$Y74)*1.08 -> 157.80579 | K74: =(207.98*$Y74)*1.08 -> 72.430533 | L74: =(233.85*$Y74)*1.08 -> 81.439947 | M74: =(280.64*$Y74)*1.08 -> 97.734901 | O74: =(20.56*$Y74)*1.08 -> 7.1601681 | P74: =(28.84*$Y74)*1.08 -> 10.043738 | Q74: =(33.93*$Y74)*1.08 -> 11.816367 | R74: =(16.43*$Y74)*1.08 -> 5.7218658 | S74: =(28.67*$Y74)*1.08 -> 9.984534 | T74: =(42.1*$Y74)*1.08 -> 14.661628 | U74: =(19.32*$Y74)*1.08 -> 6.7283292 | V74: =(21.73*$Y74)*1.08 -> 7.567629 | W74: =(26.07*$Y74)*1.08 -> 9.0790653 | Y74: 0.32246037
B75: Denmark | C75: Copenhagen | D75: EMEA | E75: =(221.26*$Y75)*1.08 -> 205.58983 | F75: =(310.41*$Y75)*1.08 -> 288.42601 | G75: =(364.87*$Y75)*1.08 -> 339.02902 | H75: =(176.83*$Y75)*1.08 -> 164.30647 | I75: =(308.58*$Y75)*1.08 -> 286.72561 | J75: =(453.13*$Y75)*1.08 -> 421.03823 | K75: =(207.98*$Y75)*1.08 -> 193.25035 | L75: =(233.85*$Y75)*1.08 -> 217.28817 | M75: =(280.64*$Y75)*1.08 -> 260.76439 | O75: =(20.56*$Y75)*1.08 -> 19.103891 | P75: =(28.84*$Y75)*1.08 -> 26.797481 | Q75: =(33.93*$Y75)*1.08 -> 31.526995 | R75: =(16.43*$Y75)*1.08 -> 15.266387 | S75: =(28.67*$Y75)*1.08 -> 26.639521 | T75: =(42.1*$Y75)*1.08 -> 39.118375 | U75: =(19.32*$Y75)*1.08 -> 17.95171 | V75: =(21.73*$Y75)*1.08 -> 20.191028 | W75: =(26.07*$Y75)*1.08 -> 24.223659 | Y75: 0.86034959
B76: Ethiopia | C76: Addis Ababa | D76: EMEA | E76: =(221.26*$Y76)*1.08 -> 126.5035 | F76: =(310.41*$Y76)*1.08 -> 177.47425 | G76: =(364.87*$Y76)*1.08 -> 208.61128 | H76: =(176.83*$Y76)*1.08 -> 101.10103 | I76: =(308.58*$Y76)*1.08 -> 176.42796 | J76: =(453.13*$Y76)*1.08 -> 259.07318 | K76: =(207.98*$Y76)*1.08 -> 118.91077 | L76: =(233.85*$Y76)*1.08 -> 133.70172 | M76: =(280.64*$Y76)*1.08 -> 160.4535 | O76: =(20.56*$Y76)*1.08 -> 11.755003 | P76: =(28.84*$Y76)*1.08 -> 16.489022 | Q76: =(33.93*$Y76)*1.08 -> 19.399185 | R76: =(16.43*$Y76)*1.08 -> 9.3937111 | S76: =(28.67*$Y76)*1.08 -> 16.391826 | T76: =(42.1*$Y76)*1.08 -> 24.070313 | U76: =(19.32*$Y76)*1.08 -> 11.046044 | V76: =(21.73*$Y76)*1.08 -> 12.42394 | W76: =(26.07*$Y76)*1.08 -> 14.905298 | Y76: 0.52939018
B77: Finland | C77: Helsinki | D77: EMEA | E77: =(221.26*$Y77)*1.08 -> 188.85577 | F77: =(310.41*$Y77)*1.08 -> 264.94947 | G77: =(364.87*$Y77)*1.08 -> 311.43363 | H77: =(176.83*$Y77)*1.08 -> 150.93269 | I77: =(308.58*$Y77)*1.08 -> 263.38748 | J77: =(453.13*$Y77)*1.08 -> 386.76767 | K77: =(207.98*$Y77)*1.08 -> 177.52067 | L77: =(233.85*$Y77)*1.08 -> 199.60193 | M77: =(280.64*$Y77)*1.08 -> 239.53938 | O77: =(20.56*$Y77)*1.08 -> 17.548923 | P77: =(28.84*$Y77)*1.08 -> 24.616291 | Q77: =(33.93*$Y77)*1.08 -> 28.960844 | R77: =(16.43*$Y77)*1.08 -> 14.023774 | S77: =(28.67*$Y77)*1.08 -> 24.471188 | T77: =(42.1*$Y77)*1.08 -> 35.934322 | U77: =(19.32*$Y77)*1.08 -> 16.490525 | V77: =(21.73*$Y77)*1.08 -> 18.547573 | W77: =(26.07*$Y77)*1.08 -> 22.251966 | Y77: 0.79032114
B78: France | C78: Paris | D78: EMEA | E78: =(221.26*$Y78)*1.08 -> 200.80867 | F78: =(310.41*$Y78)*1.08 -> 281.71843 | G78: =(364.87*$Y78)*1.08 -> 331.14462 | H78: =(176.83*$Y78)*1.08 -> 160.48539 | I78: =(308.58*$Y78)*1.08 -> 280.05757 | J78: =(453.13*$Y78)*1.08 -> 411.24664 | K78: =(207.98*$Y78)*1.08 -> 188.75615 | L78: =(233.85*$Y78)*1.08 -> 212.23496 | M78: =(280.64*$Y78)*1.08 -> 254.7001 | O78: =(20.56*$Y78)*1.08 -> 18.659614 | P78: =(28.84*$Y78)*1.08 -> 26.174284 | Q78: =(33.93*$Y78)*1.08 -> 30.793809 | R78: =(16.43*$Y78)*1.08 -> 14.911355 | S78: =(28.67*$Y78)*1.08 -> 26.019997 | T78: =(42.1*$Y78)*1.08 -> 38.208646 | U78: =(19.32*$Y78)*1.08 -> 17.534229 | V78: =(21.73*$Y78)*1.08 -> 19.72147 | W78: =(26.07*$Y78)*1.08 -> 23.660318 | Y78: 0.84034146
A79: ? | B79: Germany | C79: Berlin | D79: EMEA
B80: Germany | C80: Cologne | D80: EMEA | E80: =(221.26*$Y80)*1.08 -> 186.02714 | F80: =(310.41*$Y80)*1.08 -> 260.98113 | G80: =(364.87*$Y80)*1.08 -> 306.76906 | H80: =(176.83*$Y80)*1.08 -> 148.67206 | I80: =(308.58*$Y80)*1.08 -> 259.44253 | J80: =(453.13*$Y80)*1.08 -> 380.97477 | K80: =(207.98*$Y80)*1.08 -> 174.86181 | L80: =(233.85*$Y80)*1.08 -> 196.61234 | M80: =(280.64*$Y80)*1.08 -> 235.95162 | O80: =(20.56*$Y80)*1.08 -> 17.28608 | P80: =(28.84*$Y80)*1.08 -> 24.247594 | Q80: =(33.93*$Y80)*1.08 -> 28.527076 | R80: =(16.43*$Y80)*1.08 -> 13.81373 | S80: =(28.67*$Y80)*1.08 -> 24.104665 | T80: =(42.1*$Y80)*1.08 -> 35.396107 | U80: =(19.32*$Y80)*1.08 -> 16.243534 | V80: =(21.73*$Y80)*1.08 -> 18.269772 | W80: =(26.07*$Y80)*1.08 -> 21.918682 | Y80: 0.77848392
A81: ? | B81: Germany | C81: Frankfurt | D81: EMEA
A82: ? | B82: Germany | C82: Hamburg | D82: EMEA
A83: ? | B83: Germany | C83: Munich | D83: EMEA
A84: ? | B84: Germany | C84: Stuttgart | D84: EMEA
B85: Ghana | C85: Accra | D85: EMEA | E85: =(221.26*$Y85)*1.08 -> 145.71067 | F85: =(310.41*$Y85)*1.08 -> 204.42036 | G85: =(364.87*$Y85)*1.08 -> 240.28497 | H85: =(176.83*$Y85)*1.08 -> 116.45131 | I85: =(308.58*$Y85)*1.08 -> 203.21521 | J85: =(453.13*$Y85)*1.08 -> 298.40855 | K85: =(207.98*$Y85)*1.08 -> 136.96513 | L85: =(233.85*$Y85)*1.08 -> 154.00181 | M85: =(280.64*$Y85)*1.08 -> 184.81534 | O85: =(20.56*$Y85)*1.08 -> 13.539778 | P85: =(28.84*$Y85)*1.08 -> 18.992568 | Q85: =(33.93*$Y85)*1.08 -> 22.344585 | R85: =(16.43*$Y85)*1.08 -> 10.819969 | S85: =(28.67*$Y85)*1.08 -> 18.880615 | T85: =(42.1*$Y85)*1.08 -> 27.724935 | U85: =(19.32*$Y85)*1.08 -> 12.723177 | V85: =(21.73*$Y85)*1.08 -> 14.310281 | W85: =(26.07*$Y85)*1.08 -> 17.168386 | Y85: 0.60976808
B86: Hungary | C86: Budapest | D86: EMEA | E86: =(221.26*$Y86)*1.08 -> 148.30746 | F86: =(310.41*$Y86)*1.08 -> 208.06345 | G86: =(364.87*$Y86)*1.08 -> 244.56722 | H86: =(176.83*$Y86)*1.08 -> 118.52666 | I86: =(308.58*$Y86)*1.08 -> 206.83683 | J86: =(453.13*$Y86)*1.08 -> 303.72666 | K86: =(207.98*$Y86)*1.08 -> 139.40606 | L86: =(233.85*$Y86)*1.08 -> 156.74636 | M86: =(280.64*$Y86)*1.08 -> 188.10904 | O86: =(20.56*$Y86)*1.08 -> 13.781078 | P86: =(28.84*$Y86)*1.08 -> 19.331046 | Q86: =(33.93*$Y86)*1.08 -> 22.742801 | R86: =(16.43*$Y86)*1.08 -> 11.012798 | S86: =(28.67*$Y86)*1.08 -> 19.217097 | T86: =(42.1*$Y86)*1.08 -> 28.219037 | U86: =(19.32*$Y86)*1.08 -> 12.949924 | V86: =(21.73*$Y86)*1.08 -> 14.565313 | W86: =(26.07*$Y86)*1.08 -> 17.474354 | Y86: 0.6206351
B87: Ireland | C87: Dublin | D87: EMEA | E87: =(221.26*$Y87)*1.08 -> 175.95322 | F87: =(310.41*$Y87)*1.08 -> 246.84823 | G87: =(364.87*$Y87)*1.08 -> 290.15662 | H87: =(176.83*$Y87)*1.08 -> 140.62103 | I87: =(308.58*$Y87)*1.08 -> 245.39296 | J87: =(453.13*$Y87)*1.08 -> 360.34387 | K87: =(207.98*$Y87)*1.08 -> 165.39253 | L87: =(233.85*$Y87)*1.08 -> 185.96521 | M87: =(280.64*$Y87)*1.08 -> 223.17415 | O87: =(20.56*$Y87)*1.08 -> 16.349988 | P87: =(28.84*$Y87)*1.08 -> 22.934516 | Q87: =(33.93*$Y87)*1.08 -> 26.982251 | R87: =(16.43*$Y87)*1.08 -> 13.065676 | S87: =(28.67*$Y87)*1.08 -> 22.799326 | T87: =(42.1*$Y87)*1.08 -> 33.479304 | U87: =(19.32*$Y87)*1.08 -> 15.363899 | V87: =(21.73*$Y87)*1.08 -> 17.28041 | W87: =(26.07*$Y87)*1.08 -> 20.731721 | Y87: 0.73632673
B88: Israel | C88: Tel Aviv | D88: EMEA | E88: =(221.26*$Y88)*1.08 -> 178.75836 | F88: =(310.41*$Y88)*1.08 -> 250.78361 | G88: =(364.87*$Y88)*1.08 -> 294.78244 | H88: =(176.83*$Y88)*1.08 -> 142.86288 | I88: =(308.58*$Y88)*1.08 -> 249.30514 | J88: =(453.13*$Y88)*1.08 -> 366.08865 | K88: =(207.98*$Y88)*1.08 -> 168.0293 | L88: =(233.85*$Y88)*1.08 -> 188.92996 | M88: =(280.64*$Y88)*1.08 -> 226.73211 | O88: =(20.56*$Y88)*1.08 -> 16.610647 | P88: =(28.84*$Y88)*1.08 -> 23.300149 | Q88: =(33.93*$Y88)*1.08 -> 27.412416 | R88: =(16.43*$Y88)*1.08 -> 13.273976 | S88: =(28.67*$Y88)*1.08 -> 23.162805 | T88: =(42.1*$Y88)*1.08 -> 34.013048 | U88: =(19.32*$Y88)*1.08 -> 15.608838 | V88: =(21.73*$Y88)*1.08 -> 17.555903 | W88: =(26.07*$Y88)*1.08 -> 21.062236 | Y88: 0.74806562
B89: Italy | C89: Rome | D89: EMEA | E89: =(221.26*$Y89)*1.08 -> 116.90696 | F89: =(310.41*$Y89)*1.08 -> 164.01108 | G89: =(364.87*$Y89)*1.08 -> 192.78606 | H89: =(176.83*$Y89)*1.08 -> 93.431521 | I89: =(308.58*$Y89)*1.08 -> 163.04416 | J89: =(453.13*$Y89)*1.08 -> 239.41992 | K89: =(207.98*$Y89)*1.08 -> 109.89022 | L89: =(233.85*$Y89)*1.08 -> 123.55913 | M89: =(280.64*$Y89)*1.08 -> 148.28152 | O89: =(20.56*$Y89)*1.08 -> 10.86327 | P89: =(28.84*$Y89)*1.08 -> 15.238167 | Q89: =(33.93*$Y89)*1.08 -> 17.927566 | R89: =(16.43*$Y89)*1.08 -> 8.6811055 | S89: =(28.67*$Y89)*1.08 -> 15.148344 | T89: =(42.1*$Y89)*1.08 -> 22.244342 | U89: =(19.32*$Y89)*1.08 -> 10.208092 | V89: =(21.73*$Y89)*1.08 -> 11.481462 | W89: =(26.07*$Y89)*1.08 -> 13.774584 | Y89: 0.48923072
B90: Kenya | C90: Nairobi | D90: EMEA | E90: =(221.26*$Y90)*1.08 -> 113.91317 | F90: =(310.41*$Y90)*1.08 -> 159.81103 | G90: =(364.87*$Y90)*1.08 -> 187.84914 | H90: =(176.83*$Y90)*1.08 -> 91.038899 | I90: =(308.58*$Y90)*1.08 -> 158.86888 | J90: =(453.13*$Y90)*1.08 -> 233.28879 | K90: =(207.98*$Y90)*1.08 -> 107.07612 | L90: =(233.85*$Y90)*1.08 -> 120.39499 | M90: =(280.64*$Y90)*1.08 -> 144.48429 | O90: =(20.56*$Y90)*1.08 -> 10.58508 | P90: =(28.84*$Y90)*1.08 -> 14.847943 | Q90: =(33.93*$Y90)*1.08 -> 17.468472 | R90: =(16.43*$Y90)*1.08 -> 8.4587972 | S90: =(28.67*$Y90)*1.08 -> 14.760421 | T90: =(42.1*$Y90)*1.08 -> 21.674702 | U90: =(19.32*$Y90)*1.08 -> 9.9466805 | V90: =(21.73*$Y90)*1.08 -> 11.187441 | W90: =(26.07*$Y90)*1.08 -> 13.421841 | Y90: 0.47670235
...

Sheet TECH
A1: a | E1: TECH $/M2 | O1: TECH $/SQFT | Y1: LOCATION FACTOR | AA1: INFLATION 2022 -2023
E2: Activity | H2: Team | K2: Event | O2: Activity | R2: Team | U2: Event | Y2: BASED OFF LONDON
E3: Low | F3: Medium | G3: High | H3: Low | I3: Medium | J3: High | K3: Low | L3: Medium | M3: High | O3: Low | P3: Medium | Q3: High | R3: Low | S3: Medium | T3: High | U3: Low | V3: Medium | W3: High
B4: COUNTRY | C4: CITY | D4: REGION
B5: United States | C5: Cincinnati | D5: AMERICAS | E5: =(331.44*$Y5)*$AA5 -> 412.61379 | F5: =(339.03*$Y5)*$AA5 -> 422.06268 | G5: =(371.99*$Y5)*$AA5 -> 463.09499 | H5: =(331.44*$Y5)*$AA5 -> 412.61379 | I5: =(339.03*$Y5)*$AA5 -> 422.06268 | J5: =(371.99*$Y5)*$AA5 -> 463.09499 | K5: =(331.44*$Y5)*$AA5 -> 412.61379 | L5: =(339.03*$Y5)*$AA5 -> 422.06268 | M5: =(371.99*$Y5)*$AA5 -> 463.09499 | O5: =(30.8*$Y5)*$AA5 -> 38.343304 | P5: =(31.5*$Y5)*$AA5 -> 39.214743 | Q5: =(34.6*$Y5)*$AA5 -> 43.073972 | R5: =(30.8*$Y5)*$AA5 -> 38.343304 | S5: =(31.5*$Y5)*$AA5 -> 39.214743 | T5: =(34.6*$Y5)*$AA5 -> 43.073972 | U5: =(30.8*$Y5)*$AA5 -> 38.343304 | V5: =(31.5*$Y5)*$AA5 -> 39.214743 | W5: =(34.6*$Y5)*$AA5 -> 43.073972 | Y5: 1.1580581 | AA5: 1.075
B6: United States | C6: Charlotte | D6: AMERICAS | E6: =(331.44*$Y6)*$AA6 -> 385.42588 | F6: =(339.03*$Y6)*$AA6 -> 394.25216 | G6: =(371.99*$Y6)*$AA6 -> 432.58078 | H6: =(331.44*$Y6)*$AA6 -> 385.42588 | I6: =(339.03*$Y6)*$AA6 -> 394.25216 | J6: =(371.99*$Y6)*$AA6 -> 432.58078 | K6: =(331.44*$Y6)*$AA6 -> 385.42588 | L6: =(339.03*$Y6)*$AA6 -> 394.25216 | M6: =(371.99*$Y6)*$AA6 -> 432.58078 | O6: =(30.8*$Y6)*$AA6 -> 35.816791 | P6: =(31.5*$Y6)*$AA6 -> 36.630809 | Q6: =(34.6*$Y6)*$AA6 -> 40.235745 | R6: =(30.8*$Y6)*$AA6 -> 35.816791 | S6: =(31.5*$Y6)*$AA6 -> 36.630809 | T6: =(34.6*$Y6)*$AA6 -> 40.235745 | U6: =(30.8*$Y6)*$AA6 -> 35.816791 | V6: =(31.5*$Y6)*$AA6 -> 36.630809 | W6: =(34.6*$Y6)*$AA6 -> 40.235745 | Y6: 1.0817515 | AA6: 1.075
B7: United States | C7: Charleston | D7: AMERICAS | E7: =(331.44*$Y7)*$AA7 -> 385.42588 | F7: =(339.03*$Y7)*$AA7 -> 394.25216 | G7: =(371.99*$Y7)*$AA7 -> 432.58078 | H7: =(331.44*$Y7)*$AA7 -> 385.42588 | I7: =(339.03*$Y7)*$AA7 -> 394.25216 | J7: =(371.99*$Y7)*$AA7 -> 432.58078 | K7: =(331.44*$Y7)*$AA7 -> 385.42588 | L7: =(339.03*$Y7)*$AA7 -> 394.25216 | M7: =(371.99*$Y7)*$AA7 -> 432.58078 | O7: =(30.8*$Y7)*$AA7 -> 35.816791 | P7: =(31.5*$Y7)*$AA7 -> 36.630809 | Q7: =(34.6*$Y7)*$AA7 -> 40.235745 | R7: =(30.8*$Y7)*$AA7 -> 35.816791 | S7: =(31.5*$Y7)*$AA7 -> 36.630809 | T7: =(34.6*$Y7)*$AA7 -> 40.235745 | U7: =(30.8*$Y7)*$AA7 -> 35.816791 | V7: =(31.5*$Y7)*$AA7 -> 36.630809 | W7: =(34.6*$Y7)*$AA7 -> 40.235745 | Y7: 1.0817515 | AA7: 1.075
B8: United States | C8: Chicago | D8: AMERICAS | E8: =(331.44*$Y8)*$AA8 -> 504.96594 | F8: =(339.03*$Y8)*$AA8 -> 516.5297 | G8: =(371.99*$Y8)*$AA8 -> 566.74596 | H8: =(331.44*$Y8)*$AA8 -> 504.96594 | I8: =(339.03*$Y8)*$AA8 -> 516.5297 | J8: =(371.99*$Y8)*$AA8 -> 566.74596 | K8: =(331.44*$Y8)*$AA8 -> 504.96594 | L8: =(339.03*$Y8)*$AA8 -> 516.5297 | M8: =(371.99*$Y8)*$AA8 -> 566.74596 | O8: =(30.8*$Y8)*$AA8 -> 46.925389 | P8: =(31.5*$Y8)*$AA8 -> 47.991876 | Q8: =(34.6*$Y8)*$AA8 -> 52.714886 | R8: =(30.8*$Y8)*$AA8 -> 46.925389 | S8: =(31.5*$Y8)*$AA8 -> 47.991876 | T8: =(34.6*$Y8)*$AA8 -> 52.714886 | U8: =(30.8*$Y8)*$AA8 -> 46.925389 | V8: =(31.5*$Y8)*$AA8 -> 47.991876 | W8: =(34.6*$Y8)*$AA8 -> 52.714886 | Y8: 1.4172573 | AA8: 1.075
B9: United States | C9: Cleveland | D9: AMERICAS | E9: =(331.44*$Y9)*$AA9 -> 400.21644 | F9: =(339.03*$Y9)*$AA9 -> 409.38142 | G9: =(371.99*$Y9)*$AA9 -> 449.18088 | H9: =(331.44*$Y9)*$AA9 -> 400.21644 | I9: =(339.03*$Y9)*$AA9 -> 409.38142 | J9: =(371.99*$Y9)*$AA9 -> 449.18088 | K9: =(331.44*$Y9)*$AA9 -> 400.21644 | L9: =(339.03*$Y9)*$AA9 -> 409.38142 | M9: =(371.99*$Y9)*$AA9 -> 449.18088 | O9: =(30.8*$Y9)*$AA9 -> 37.191245 | P9: =(31.5*$Y9)*$AA9 -> 38.0365 | Q9: =(34.6*$Y9)*$AA9 -> 41.779775 | R9: =(30.8*$Y9)*$AA9 -> 37.191245 | S9: =(31.5*$Y9)*$AA9 -> 38.0365 | T9: =(34.6*$Y9)*$AA9 -> 41.779775 | U9: =(30.8*$Y9)*$AA9 -> 37.191245 | V9: =(31.5*$Y9)*$AA9 -> 38.0365 | W9: =(34.6*$Y9)*$AA9 -> 41.779775 | Y9: 1.1232632 | AA9: 1.075
B10: United States | C10: Boston | D10: AMERICAS | E10: =(331.44*$Y10)*$AA10 -> 491.58783 | F10: =(339.03*$Y10)*$AA10 -> 502.84523 | G10: =(371.99*$Y10)*$AA10 -> 551.73111 | H10: =(331.44*$Y10)*$AA10 -> 491.58783 | I10: =(339.03*$Y10)*$AA10 -> 502.84523 | J10: =(371.99*$Y10)*$AA10 -> 551.73111 | K10: =(331.44*$Y10)*$AA10 -> 491.58783 | L10: =(339.03*$Y10)*$AA10 -> 502.84523 | M10: =(371.99*$Y10)*$AA10 -> 551.73111 | O10: =(30.8*$Y10)*$AA10 -> 45.682191 | P10: =(31.5*$Y10)*$AA10 -> 46.720422 | Q10: =(34.6*$Y10)*$AA10 -> 51.318305 | R10: =(30.8*$Y10)*$AA10 -> 45.682191 | S10: =(31.5*$Y10)*$AA10 -> 46.720422 | T10: =(34.6*$Y10)*$AA10 -> 51.318305 | U10: =(30.8*$Y10)*$AA10 -> 45.682191 | V10: =(31.5*$Y10)*$AA10 -> 46.720422 | W10: =(34.6*$Y10)*$AA10 -> 51.318305 | Y10: 1.3797098 | AA10: 1.075
B11: United States | C11: Baltimore | D11: AMERICAS | E11: =(331.44*$Y11)*$AA11 -> 401.92826 | F11: =(339.03*$Y11)*$AA11 -> 411.13244 | G11: =(371.99*$Y11)*$AA11 -> 451.10214 | H11: =(331.44*$Y11)*$AA11 -> 401.92826 | I11: =(339.03*$Y11)*$AA11 -> 411.13244 | J11: =(371.99*$Y11)*$AA11 -> 451.10214 | K11: =(331.44*$Y11)*$AA11 -> 401.92826 | L11: =(339.03*$Y11)*$AA11 -> 411.13244 | M11: =(371.99*$Y11)*$AA11 -> 451.10214 | O11: =(30.8*$Y11)*$AA11 -> 37.350321 | P11: =(31.5*$Y11)*$AA11 -> 38.199192 | Q11: =(34.6*$Y11)*$AA11 -> 41.958477 | R11: =(30.8*$Y11)*$AA11 -> 37.350321 | S11: =(31.5*$Y11)*$AA11 -> 38.199192 | T11: =(34.6*$Y11)*$AA11 -> 41.958477 | U11: =(30.8*$Y11)*$AA11 -> 37.350321 | V11: =(31.5*$Y11)*$AA11 -> 38.199192 | W11: =(34.6*$Y11)*$AA11 -> 41.958477 | Y11: 1.1280677 | AA11: 1.075
B12: United States | C12: Columbus | D12: AMERICAS | E12: =(331.44*$Y12)*$AA12 -> 391.00175 | F12: =(339.03*$Y12)*$AA12 -> 399.95572 | G12: =(371.99*$Y12)*$AA12 -> 438.83883 | H12: =(331.44*$Y12)*$AA12 -> 391.00175 | I12: =(339.03*$Y12)*$AA12 -> 399.95572 | J12: =(371.99*$Y12)*$AA12 -> 438.83883 | K12: =(331.44*$Y12)*$AA12 -> 391.00175 | L12: =(339.03*$Y12)*$AA12 -> 399.95572 | M12: =(371.99*$Y12)*$AA12 -> 438.83883 | O12: =(30.8*$Y12)*$AA12 -> 36.334944 | P12: =(31.5*$Y12)*$AA12 -> 37.160739 | Q12: =(34.6*$Y12)*$AA12 -> 40.817827 | R12: =(30.8*$Y12)*$AA12 -> 36.334944 | S12: =(31.5*$Y12)*$AA12 -> 37.160739 | T12: =(34.6*$Y12)*$AA12 -> 40.817827 | U12: =(30.8*$Y12)*$AA12 -> 36.334944 | V12: =(31.5*$Y12)*$AA12 -> 37.160739 | W12: =(34.6*$Y12)*$AA12 -> 40.817827 | Y12: 1.0974009 | AA12: 1.075
B13: United States | C13: Austin | D13: AMERICAS | E13: =(331.44*$Y13)*$AA13 -> 366.97874 | F13: =(339.03*$Y13)*$AA13 -> 375.38258 | G13: =(371.99*$Y13)*$AA13 -> 411.87673 | H13: =(331.44*$Y13)*$AA13 -> 366.97874 | I13: =(339.03*$Y13)*$AA13 -> 375.38258 | J13: =(371.99*$Y13)*$AA13 -> 411.87673 | K13: =(331.44*$Y13)*$AA13 -> 366.97874 | L13: =(339.03*$Y13)*$AA13 -> 375.38258 | M13: =(371.99*$Y13)*$AA13 -> 411.87673 | O13: =(30.8*$Y13)*$AA13 -> 34.102538 | P13: =(31.5*$Y13)*$AA13 -> 34.877596 | Q13: =(34.6*$Y13)*$AA13 -> 38.309994 | R13: =(30.8*$Y13)*$AA13 -> 34.102538 | S13: =(31.5*$Y13)*$AA13 -> 34.877596 | T13: =(34.6*$Y13)*$AA13 -> 38.309994 | U13: =(30.8*$Y13)*$AA13 -> 34.102538 | V13: =(31.5*$Y13)*$AA13 -> 34.877596 | W13: =(34.6*$Y13)*$AA13 -> 38.309994 | Y13: 1.029977 | AA13: 1.075
B14: United States | C14: Atlanta | D14: AMERICAS | E14: =(331.44*$Y14)*$AA14 -> 387.2321 | F14: =(339.03*$Y14)*$AA14 -> 396.09974 | G14: =(371.99*$Y14)*$AA14 -> 434.60798 | H14: =(331.44*$Y14)*$AA14 -> 387.2321 | I14: =(339.03*$Y14)*$AA14 -> 396.09974 | J14: =(371.99*$Y14)*$AA14 -> 434.60798 | K14: =(331.44*$Y14)*$AA14 -> 387.2321 | L14: =(339.03*$Y14)*$AA14 -> 396.09974 | M14: =(371.99*$Y14)*$AA14 -> 434.60798 | O14: =(30.8*$Y14)*$AA14 -> 35.984639 | P14: =(31.5*$Y14)*$AA14 -> 36.802471 | Q14: =(34.6*$Y14)*$AA14 -> 40.424302 | R14: =(30.8*$Y14)*$AA14 -> 35.984639 | S14: =(31.5*$Y14)*$AA14 -> 36.802471 | T14: =(34.6*$Y14)*$AA14 -> 40.424302 | U14: =(30.8*$Y14)*$AA14 -> 35.984639 | V14: =(31.5*$Y14)*$AA14 -> 36.802471 | W14: =(34.6*$Y14)*$AA14 -> 40.424302 | Y14: 1.0868209 | AA14: 1.075
B15: United States | C15: Dallas | D15: AMERICAS | E15: =(331.44*$Y15)*$AA15 -> 368.80262 | F15: =(339.03*$Y15)*$AA15 -> 377.24822 | G15: =(371.99*$Y15)*$AA15 -> 413.92374 | H15: =(331.44*$Y15)*$AA15 -> 368.80262 | I15: =(339.03*$Y15)*$AA15 -> 377.24822 | J15: =(371.99*$Y15)*$AA15 -> 413.92374 | K15: =(331.44*$Y15)*$AA15 -> 368.80262 | L15: =(339.03*$Y15)*$AA15 -> 377.24822 | M15: =(371.99*$Y15)*$AA15 -> 413.92374 | O15: =(30.8*$Y15)*$AA15 -> 34.272027 | P15: =(31.5*$Y15)*$AA15 -> 35.050937 | Q15: =(34.6*$Y15)*$AA15 -> 38.500394 | R15: =(30.8*$Y15)*$AA15 -> 34.272027 | S15: =(31.5*$Y15)*$AA15 -> 35.050937 | T15: =(34.6*$Y15)*$AA15 -> 38.500394 | U15: =(30.8*$Y15)*$AA15 -> 34.272027 | V15: =(31.5*$Y15)*$AA15 -> 35.050937 | W15: =(34.6*$Y15)*$AA15 -> 38.500394 | Y15: 1.035096 | AA15: 1.075
B16: United States | C16: Denver | D16: AMERICAS | E16: =(331.44*$Y16)*$AA16 -> 393.93372 | F16: =(339.03*$Y16)*$AA16 -> 402.95483 | G16: =(371.99*$Y16)*$AA16 -> 442.12951 | H16: =(331.44*$Y16)*$AA16 -> 393.93372 | I16: =(339.03*$Y16)*$AA16 -> 402.95483 | J16: =(371.99*$Y16)*$AA16 -> 442.12951 | K16: =(331.44*$Y16)*$AA16 -> 393.93372 | L16: =(339.03*$Y16)*$AA16 -> 402.95483 | M16: =(371.99*$Y16)*$AA16 -> 442.12951 | O16: =(30.8*$Y16)*$AA16 -> 36.607406 | P16: =(31.5*$Y16)*$AA16 -> 37.439392 | Q16: =(34.6*$Y16)*$AA16 -> 41.123904 | R16: =(30.8*$Y16)*$AA16 -> 36.607406 | S16: =(31.5*$Y16)*$AA16 -> 37.439392 | T16: =(34.6*$Y16)*$AA16 -> 41.123904 | U16: =(30.8*$Y16)*$AA16 -> 36.607406 | V16: =(31.5*$Y16)*$AA16 -> 37.439392 | W16: =(34.6*$Y16)*$AA16 -> 41.123904 | Y16: 1.1056299 | AA16: 1.075
... B78: France | C78: Paris | D78: EMEA | E78: =(331.44*$Y78)*$AA78 -> 292.44891 | F78: =(339.03*$Y78)*$AA78 -> 299.14601 | G78: =(371.99*$Y78)*$AA78 -> 328.22855 | H78: =(331.44*$Y78)*$AA78 -> 292.44891 | I78: =(339.03*$Y78)*$AA78 -> 299.14601 | J78: =(371.99*$Y78)*$AA78 -> 328.22855 | K78: =(331.44*$Y78)*$AA78 -> 292.44891 | L78: =(339.03*$Y78)*$AA78 -> 299.14601 | M78: =(371.99*$Y78)*$AA78 -> 328.22855 | O78: =(30.8*$Y78)*$AA78 -> 27.176643 | P78: =(31.5*$Y78)*$AA78 -> 27.794294 | Q78: =(34.6*$Y78)*$AA78 -> 30.529605 | R78: =(30.8*$Y78)*$AA78 -> 27.176643 | S78: =(31.5*$Y78)*$AA78 -> 27.794294 | T78: =(34.6*$Y78)*$AA78 -> 30.529605 | U78: =(30.8*$Y78)*$AA78 -> 27.176643 | V78: =(31.5*$Y78)*$AA78 -> 27.794294 | W78: =(34.6*$Y78)*$AA78 -> 30.529605 | Y78: 0.84034146 | AA78: 1.05
A79: ? | B79: Germany | C79: Berlin | D79: EMEA | E79: =(331.44*$Y79)*$AA79 -> 0 | F79: =(339.03*$Y79)*$AA79 -> 0 | G79: =(371.99*$Y79)*$AA79 -> 0 | H79: =(331.44*$Y79)*$AA79 -> 0 | I79: =(339.03*$Y79)*$AA79 -> 0 | J79: =(371.99*$Y79)*$AA79 -> 0 | K79: =(331.44*$Y79)*$AA79 -> 0 | L79: =(339.03*$Y79)*$AA79 -> 0 | M79: =(371.99*$Y79)*$AA79 -> 0 | O79: =(30.8*$Y79)*$AA79 -> 0 | P79: =(31.5*$Y79)*$AA79 -> 0 | Q79: =(34.6*$Y79)*$AA79 -> 0 | R79: =(30.8*$Y79)*$AA79 -> 0 | S79: =(31.5*$Y79)*$AA79 -> 0 | T79: =(34.6*$Y79)*$AA79 -> 0 | U79: =(30.8*$Y79)*$AA79 -> 0 | V79: =(31.5*$Y79)*$AA79 -> 0 | W79: =(34.6*$Y79)*$AA79 -> 0 | AA79: 1.075
B80: Germany | C80: Cologne | D80: EMEA | E80: =(331.44*$Y80)*$AA80 -> 277.37226 | F80: =(339.03*$Y80)*$AA80 -> 283.72411 | G80: =(371.99*$Y80)*$AA80 -> 311.30735 | H80: =(331.44*$Y80)*$AA80 -> 277.37226 | I80: =(339.03*$Y80)*$AA80 -> 283.72411 | J80: =(371.99*$Y80)*$AA80 -> 311.30735 | K80: =(331.44*$Y80)*$AA80 -> 277.37226 | L80: =(339.03*$Y80)*$AA80 -> 283.72411 | M80: =(371.99*$Y80)*$AA80 -> 311.30735 | O80: =(30.8*$Y80)*$AA80 -> 25.775602 | P80: =(31.5*$Y80)*$AA80 -> 26.361412 | Q80: =(34.6*$Y80)*$AA80 -> 28.955709 | R80: =(30.8*$Y80)*$AA80 -> 25.775602 | S80: =(31.5*$Y80)*$AA80 -> 26.361412 | T80: =(34.6*$Y80)*$AA80 -> 28.955709 | U80: =(30.8*$Y80)*$AA80 -> 25.775602 | V80: =(31.5*$Y80)*$AA80 -> 26.361412 | W80: =(34.6*$Y80)*$AA80 -> 28.955709 | Y80: 0.77848392 | AA80: 1.075
A81: ? | B81: Germany | C81: Frankfurt | D81: EMEA | E81: =(331.44*$Y81)*$AA81 -> 0 | F81: =(339.03*$Y81)*$AA81 -> 0 | G81: =(371.99*$Y81)*$AA81 -> 0 | H81: =(331.44*$Y81)*$AA81 -> 0 | I81: =(339.03*$Y81)*$AA81 -> 0 | J81: =(371.99*$Y81)*$AA81 -> 0 | K81: =(331.44*$Y81)*$AA81 -> 0 | L81: =(339.03*$Y81)*$AA81 -> 0 | M81: =(371.99*$Y81)*$AA81 -> 0 | O81: =(30.8*$Y81)*$AA81 -> 0 | P81: =(31.5*$Y81)*$AA81 -> 0 | Q81: =(34.6*$Y81)*$AA81 -> 0 | R81: =(30.8*$Y81)*$AA81 -> 0 | S81: =(31.5*$Y81)*$AA81 -> 0 | T81: =(34.6*$Y81)*$AA81 -> 0 | U81: =(30.8*$Y81)*$AA81 -> 0 | V81: =(31.5*$Y81)*$AA81 -> 0 | W81: =(34.6*$Y81)*$AA81 -> 0 | AA81: 1.075
A82: ? | B82: Germany | C82: Hamburg | D82: EMEA | E82: =(331.44*$Y82)*$AA82 -> 0 | F82: =(339.03*$Y82)*$AA82 -> 0 | G82: =(371.99*$Y82)*$AA82 -> 0 | H82: =(331.44*$Y82)*$AA82 -> 0 | I82: =(339.03*$Y82)*$AA82 -> 0 | J82: =(371.99*$Y82)*$AA82 -> 0 | K82: =(331.44*$Y82)*$AA82 -> 0 | L82: =(339.03*$Y82)*$AA82 -> 0 | M82: =(371.99*$Y82)*$AA82 -> 0 | O82: =(30.8*$Y82)*$AA82 -> 0 | P82: =(31.5*$Y82)*$AA82 -> 0 | Q82: =(34.6*$Y82)*$AA82 -> 0 | R82: =(30.8*$Y82)*$AA82 -> 0 | S82: =(31.5*$Y82)*$AA82 -> 0 | T82: =(34.6*$Y82)*$AA82 -> 0 | U82: =(30.8*$Y82)*$AA82 -> 0 | V82: =(31.5*$Y82)*$AA82 -> 0 | W82: =(34.6*$Y82)*$AA82 -> 0 | AA82: 1.075
A83: ? | B83: Germany | C83: Munich | D83: EMEA | E83: =(331.44*$Y83)*$AA83 -> 0 | F83: =(339.03*$Y83)*$AA83 -> 0 | G83: =(371.99*$Y83)*$AA83 -> 0 | H83: =(331.44*$Y83)*$AA83 -> 0 | I83: =(339.03*$Y83)*$AA83 -> 0 | J83: =(371.99*$Y83)*$AA83 -> 0 | K83: =(331.44*$Y83)*$AA83 -> 0 | L83: =(339.03*$Y83)*$AA83 -> 0 | M83: =(371.99*$Y83)*$AA83 -> 0 | O83: =(30.8*$Y83)*$AA83 -> 0 | P83: =(31.5*$Y83)*$AA83 -> 0 | Q83: =(34.6*$Y83)*$AA83 -> 0 | R83: =(30.8*$Y83)*$AA83 -> 0 | S83: =(31.5*$Y83)*$AA83 -> 0 | T83: =(34.6*$Y83)*$AA83 -> 0 | U83: =(30.8*$Y83)*$AA83 -> 0 | V83: =(31.5*$Y83)*$AA83 -> 0 | W83: =(34.6*$Y83)*$AA83 -> 0 | AA83: 1.075
A84: ? | B84: Germany | C84: Stuttgart | D84: EMEA | E84: =(331.44*$Y84)*$AA84 -> 0 | F84: =(339.03*$Y84)*$AA84 -> 0 | G84: =(371.99*$Y84)*$AA84 -> 0 | H84: =(331.44*$Y84)*$AA84 -> 0 | I84: =(339.03*$Y84)*$AA84 -> 0 | J84: =(371.99*$Y84)*$AA84 -> 0 | K84: =(331.44*$Y84)*$AA84 -> 0 | L84: =(339.03*$Y84)*$AA84 -> 0 | M84: =(371.99*$Y84)*$AA84 -> 0 | O84: =(30.8*$Y84)*$AA84 -> 0 | P84: =(31.5*$Y84)*$AA84 -> 0 | Q84: =(34.6*$Y84)*$AA84 -> 0 | R84: =(30.8*$Y84)*$AA84 -> 0 | S84: =(31.5*$Y84)*$AA84 -> 0 | T84: =(34.6*$Y84)*$AA84 -> 0 | U84: =(30.8*$Y84)*$AA84 -> 0 | V84: =(31.5*$Y84)*$AA84 -> 0 | W84: =(34.6*$Y84)*$AA84 -> 0 | AA84: 1.075
B85: Ghana | C85: Accra | D85: EMEA | E85: =(331.44*$Y85)*$AA85 -> 210.18559 | F85: =(339.03*$Y85)*$AA85 -> 214.99886 | G85: =(371.99*$Y85)*$AA85 -> 235.90073 | H85: =(331.44*$Y85)*$AA85 -> 210.18559 | I85: =(339.03*$Y85)*$AA85 -> 214.99886 | J85: =(371.99*$Y85)*$AA85 -> 235.90073 | K85: =(331.44*$Y85)*$AA85 -> 210.18559 | L85: =(339.03*$Y85)*$AA85 -> 214.99886 | M85: =(371.99*$Y85)*$AA85 -> 235.90073 | O85: =(30.8*$Y85)*$AA85 -> 19.532091 | P85: =(31.5*$Y85)*$AA85 -> 19.976002 | Q85: =(34.6*$Y85)*$AA85 -> 21.941895 | R85: =(30.8*$Y85)*$AA85 -> 19.532091 | S85: =(31.5*$Y85)*$AA85 -> 19.976002 | T85: =(34.6*$Y85)*$AA85 -> 21.941895 | U85: =(30.8*$Y85)*$AA85 -> 19.532091 | V85: =(31.5*$Y85)*$AA85 -> 19.976002 | W85: =(34.6*$Y85)*$AA85 -> 21.941895 | Y85: 0.60976808 | AA85: 1.04
B86: Hungary | C86: Budapest | D86: EMEA | E86: =(331.44*$Y86)*$AA86 -> 215.98846 | F86: =(339.03*$Y86)*$AA86 -> 220.93462 | G86: =(371.99*$Y86)*$AA86 -> 242.41356 | H86: =(331.44*$Y86)*$AA86 -> 215.98846 | I86: =(339.03*$Y86)*$AA86 -> 220.93462 | J86: =(371.99*$Y86)*$AA86 -> 242.41356 | K86: =(331.44*$Y86)*$AA86 -> 215.98846 | L86: =(339.03*$Y86)*$AA86 -> 220.93462 | M86: =(371.99*$Y86)*$AA86 -> 242.41356 | O86: =(30.8*$Y86)*$AA86 -> 20.071339 | P86: =(31.5*$Y86)*$AA86 -> 20.527506 | Q86: =(34.6*$Y86)*$AA86 -> 22.547673 | R86: =(30.8*$Y86)*$AA86 -> 20.071339 | S86: =(31.5*$Y86)*$AA86 -> 20.527506 | T86: =(34.6*$Y86)*$AA86 -> 22.547673 | U86: =(30.8*$Y86)*$AA86 -> 20.071339 | V86: =(31.5*$Y86)*$AA86 -> 20.527506 | W86: =(34.6*$Y86)*$AA86 -> 22.547673 | Y86: 0.6206351 | AA86: 1.05
B87: Ireland | C87: Dublin | D87: EMEA | E87: =(331.44*$Y87)*$AA87 -> 261.1315 | F87: =(339.03*$Y87)*$AA87 -> 267.11143 | G87: =(371.99*$Y87)*$AA87 -> 293.07961 | H87: =(331.44*$Y87)*$AA87 -> 261.1315 | I87: =(339.03*$Y87)*$AA87 -> 267.11143 | J87: =(371.99*$Y87)*$AA87 -> 293.07961 | K87: =(331.44*$Y87)*$AA87 -> 261.1315 | L87: =(339.03*$Y87)*$AA87 -> 267.11143 | M87: =(371.99*$Y87)*$AA87 -> 293.07961 | O87: =(30.8*$Y87)*$AA87 -> 24.266384 | P87: =(31.5*$Y87)*$AA87 -> 24.817892 | Q87: =(34.6*$Y87)*$AA87 -> 27.260288 | R87: =(30.8*$Y87)*$AA87 -> 24.266384 | S87: =(31.5*$Y87)*$AA87 -> 24.817892 | T87: =(34.6*$Y87)*$AA87 -> 27.260288 | U87: =(30.8*$Y87)*$AA87 -> 24.266384 | V87: =(31.5*$Y87)*$AA87 -> 24.817892 | W87: =(34.6*$Y87)*$AA87 -> 27.260288 | Y87: 0.73632673 | AA87: 1.07
B88: Israel | C88: Tel Aviv | D88: EMEA | E88: =(331.44*$Y88)*$AA88 -> 269.26161 | F88: =(339.03*$Y88)*$AA88 -> 275.42772 | G88: =(371.99*$Y88)*$AA88 -> 302.2044 | H88: =(331.44*$Y88)*$AA88 -> 269.26161 | I88: =(339.03*$Y88)*$AA88 -> 275.42772 | J88: =(371.99*$Y88)*$AA88 -> 302.2044 | K88: =(331.44*$Y88)*$AA88 -> 269.26161 | L88: =(339.03*$Y88)*$AA88 -> 275.42772 | M88: =(371.99*$Y88)*$AA88 -> 302.2044 | O88: =(30.8*$Y88)*$AA88 -> 25.021897 | P88: =(31.5*$Y88)*$AA88 -> 25.590577 | Q88: =(34.6*$Y88)*$AA88 -> 28.109015 | R88: =(30.8*$Y88)*$AA88 -> 25.021897 | S88: =(31.5*$Y88)*$AA88 -> 25.590577 | T88: =(34.6*$Y88)*$AA88 -> 28.109015 | U88: =(30.8*$Y88)*$AA88 -> 25.021897 | V88: =(31.5*$Y88)*$AA88 -> 25.590577 | W88: =(34.6*$Y88)*$AA88 -> 28.109015 | Y88: 0.74806562 | AA88: 1.086
B89: Italy | C89: Rome | D89: EMEA | E89: =(331.44*$Y89)*$AA89 -> 174.31193 | F89: =(339.03*$Y89)*$AA89 -> 178.30368 | G89: =(371.99*$Y89)*$AA89 -> 195.6381 | H89: =(331.44*$Y89)*$AA89 -> 174.31193 | I89: =(339.03*$Y89)*$AA89 -> 178.30368 | J89: =(371.99*$Y89)*$AA89 -> 195.6381 | K89: =(331.44*$Y89)*$AA89 -> 174.31193 | L89: =(339.03*$Y89)*$AA89 -> 178.30368 | M89: =(371.99*$Y89)*$AA89 -> 195.6381 | O89: =(30.8*$Y89)*$AA89 -> 16.198429 | P89: =(31.5*$Y89)*$AA89 -> 16.566575 | Q89: =(34.6*$Y89)*$AA89 -> 18.196936 | R89: =(30.8*$Y89)*$AA89 -> 16.198429 | S89: =(31.5*$Y89)*$AA89 -> 16.566575 | T89: =(34.6*$Y89)*$AA89 -> 18.196936 | U89: =(30.8*$Y89)*$AA89 -> 16.198429 | V89: =(31.5*$Y89)*$AA89 -> 16.566575 | W89: =(34.6*$Y89)*$AA89 -> 18.196936 | Y89: 0.48923072 | AA89: 1.075
B90: Kenya | C90: Nairobi | D90: EMEA | E90: =(331.44*$Y90)*$AA90 -> 164.31816 | F90: =(339.03*$Y90)*$AA90 -> 168.08105 | G90: =(371.99*$Y90)*$AA90 -> 184.42165 | H90: =(331.44*$Y90)*$AA90 -> 164.31816 | I90: =(339.03*$Y90)*$AA90 -> 168.08105 | J90: =(371.99*$Y90)*$AA90 -> 184.42165 | K90: =(331.44*$Y90)*$AA90 -> 164.31816 | L90: =(339.03*$Y90)*$AA90 -> 168.08105 | M90: =(371.99*$Y90)*$AA90 -> 184.42165 | O90: =(30.8*$Y90)*$AA90 -> 15.26973 | P90: =(31.5*$Y90)*$AA90 -> 15.616769 | Q90: =(34.6*$Y90)*$AA90 -> 17.153657 | R90: =(30.8*$Y90)*$AA90 -> 15.26973 | S90: =(31.5*$Y90)*$AA90 -> 15.616769 | T90: =(34.6*$Y90)*$AA90 -> 17.153657 | U90: =(30.8*$Y90)*$AA90 -> 15.26973 | V90: =(31.5*$Y90)*$AA90 -> 15.616769 | W90: =(34.6*$Y90)*$AA90 -> 17.153657 | Y90: 0.47670235 | AA90: 1.04
B91: Luxembourg | C91: Luxembourg | D91: EMEA | E91: =(331.44*$Y91)*$AA91 -> 224.40919 | F91: =(339.03*$Y91)*$AA91 -> 229.54817 | G91: =(371.99*$Y91)*$AA91 -> 251.86451 | H91: =(331.44*$Y91)*$AA91 -> 224.40919 | I91: =(339.03*$Y91)*$AA91 -> 229.54817 | J91: =(371.99*$Y91)*$AA91 -> 251.86451 | K91: =(331.44*$Y91)*$AA91 -> 224.40919 | L91: =(339.03*$Y91)*$AA91 -> 229.54817 | M91: =(371.99*$Y91)*$AA91 -> 251.86451 | O91: =(30.8*$Y91)*$AA91 -> 20.853859 | P91: =(31.5*$Y91)*$AA91 -> 21.32781 | Q91: =(34.6*$Y91)*$AA91 -> 23.426737 | R91: =(30.8*$Y91)*$AA91 -> 20.853859 | S91: =(31.5*$Y91)*$AA91 -> 21.32781 | T91: =(34.6*$Y91)*$AA91 -> 23.426737 | U91: =(30.8*$Y91)*$AA91 -> 20.853859 | V91: =(31.5*$Y91)*$AA91 -> 21.32781 | W91: =(34.6*$Y91)*$AA91 -> 23.426737 | Y91: 0.64483175 | AA91: 1.05
B92: Morocco | C92: Casablanca | D92: EMEA | E92: =(331.44*$Y92)*$AA92 -> 271.85504 | F92: =(339.03*$Y92)*$AA92 -> 278.08054 | G92: =(371.99*$Y92)*$AA92 -> 305.11512 | H92: =(331.44*$Y92)*$AA92 -> 271.85504 | I92: =(339.03*$Y92)*$AA92 -> 278.08054 | J92: =(371.99*$Y92)*$AA92 -> 305.11512 | K92: =(331.44*$Y92)*$AA92 -> 271.85504 | L92: =(339.03*$Y92)*$AA92 -> 278.08054 | M92: =(371.99*$Y92)*$AA92 -> 305.11512 | O92: =(30.8*$Y92)*$AA92 -> 25.262899 | P92: =(31.5*$Y92)*$AA92 -> 25.837056 | Q92: =(34.6*$Y92)*$AA92 -> 28.37975 | R92: =(30.8*$Y92)*$AA92 -> 25.262899 | S92: =(31.5*$Y92)*$AA92 -> 25.837056 | T92: =(34.6*$Y92)*$AA92 -> 28.37975 | U92: =(30.8*$Y92)*$AA92 -> 25.262899 | V92: =(31.5*$Y92)*$AA92 -> 25.837056 | W92: =(34.6*$Y92)*$AA92 -> 28.37975 | Y92: 0.78867691 | AA92: 1.04
B93: Netherlands | C93: Amsterdam | D93: EMEA | E93: =(331.44*$Y93)*$AA93 -> 167.99828 | F93: =(339.03*$Y93)*$AA93 -> 171.84545 | G93: =(371.99*$Y93)*$AA93 -> 188.55201 | H93: =(331.44*$Y93)*$AA93 -> 167.99828 | I93: =(339.03*$Y93)*$AA93 -> 171.84545 | J93: =(371.99*$Y93)*$AA93 -> 188.55201 | K93: =(331.44*$Y93)*$AA93 -> 167.99828 | L93: =(339.03*$Y93)*$AA93 -> 171.84545 | M93: =(371.99*$Y93)*$AA93 -> 188.55201 | O93: =(30.8*$Y93)*$AA93 -> 15.611715 | P93: =(31.5*$Y93)*$AA93 -> 15.966527 | Q93: =(34.6*$Y93)*$AA93 -> 17.537836 | R93: =(30.8*$Y93)*$AA93 -> 15.611715 | S93: =(31.5*$Y93)*$AA93 -> 15.966527 | T93: =(34.6*$Y93)*$AA93 -> 17.537836 | U93: =(30.8*$Y93)*$AA93 -> 15.611715 | V93: =(31.5*$Y93)*$AA93 -> 15.966527 | W93: =(34.6*$Y93)*$AA93 -> 17.537836 | Y93: 0.48044917 | AA93: 1.055
